Workbook

Sheet State Summary Graphs
B2: State IC3 Data
H3: System Intrusion Group | M3: Threat to Personnel via Network | P3: Theft of Data via Network
B4: Year | C4: City Population | D4: Column1 | E4: Column2 | F4: Column3 | G4: Crimes | H4: Data Breach | I4: Personal Data Breach | J4: Malware | K4: Phishing | L4: Ransomware | M4: Crimes Against Children | N4: Extortion | O4: Threats/Stalking/Harassment/Terrorism | P4: IPR/Counterfeit | Q4: Identify Theft | R4: BEC
B5: 2016 | C5: ='2016_IC3 State to City'!$E$6 -> 177746 | H5: 53 | I5: 429 | J5: 60 | K5: 298 | L5: 49 | M5: 14 | N5: 361 | O5: 276 | P5: 44 | Q5: 281 | R5: 161
B6: 2017 | C6: ='2017_IC3 State to City'!$E$6 -> 179530 | H6: 53 | I6: 490 | J6: 43 | K6: 347 | L6: 33 | M6: 19 | N6: 290 | O6: 230 | P6: 38 | Q6: 332 | R6: 184
B7: 2018 | C7: ='2018_IC3 State to City'!$E$6 -> 181918 | H7: 28 | I7: 697 | J7: 23 | K7: 311 | L7: 20 | M7: 28 | N7: 759 | O7: 262 | P7: 25 | Q7: 407 | R7: 297
B8: 2019 | C8: ='2019_IC3 State to City'!$E$6 -> 182799 | H8: 21 | I8: 507 | J8: 46 | K8: 310 | L8: 34 | M8: 23 | N8: 725 | O8: 199 | P8: 58 | Q8: 289 | R8: 331
B9: 2020 | C9: ='2020_IC3 State to City'!$E$6 -> 181560 | H9: 29 | I9: 714 | J9: 18 | K9: 379 | L9: 34 | M9: 60 | N9: 1185 | O9: 267 | P9: 75 | Q9: 419 | R9: 249
B10: 2021 | C10: ='2021_IC3 State to City'!$E$6 -> 181163 | H10: 21 | I10: 742 | J10: 11 | K10: 438 | L10: 47 | M10: 29 | N10: 628 | O10: 172 | P10: 60 | Q10: 529 | R10: 321
B11: 2022 | C11: ='2022_IC3 State to City'!$E$6 -> 184086 | H11: 44 | I11: 903 | J11: 9 | K11: 296 | L11: 31 | M11: 54 | N11: 695 | O11: 28 | P11: 19 | Q11: 539 | R11: ='2022_IC3 State to City'!$E$8 -> 416

Sheet 2016_IC3 State to City
B4: REF URL | C4: Decription | D4: Unit | E4: Value | F4: Value/State Population | G4: Estimated In-City Victims, 2022, As if IC3 Victim Complaint | H4: State Victim Loss | I4: Even Loss per State Victim Count | J4: Projected In-City Victim Loss | K4: State Subject (Perpetrator) Count | L4: Subject (Perpetrator) to State Population | M4: Estimated Subject to City Population | N4: State Subject Losses (Perpetrator gained X dollars) | O4: Even Loss per State Subject | P4: Estimated In-City Subject Losses (Perpetrator Take from Victim)
B5: https://www.census.gov/quickfacts/fact/table/TN/PST045222 | C5: TN Population in 2016 | D5: Population Estimate | E5: 6646010 | F5: Raw Value | G5: (Victim Count/State Population ) * City Population | J5: Estimated In-City Victims * Even Loss per State Victim | P5: Subject to City * Even Loss per State Subject
B6: https://www.census.gov/quickfacts/chattanoogacitytennessee | C6: Chattanooga Population in 2016 | D6: Population Estimate | E6: 177746
B7: https://www.ic3.gov/Media/PDF/AnnualReport/2016State/StateReport.aspx#?s=47 | C7: Advanced Fee | D7: State Victim Count | E7: 276 | F7: =E7/E5 -> 4.1528677e-05 | G7: =ROUNDDOWN(F7*E6,0) -> 7 | H7: 1211869 | I7: =H7/E7 -> 4390.8297 | J7: =I7*G7 -> 30735.808 | K7: 65 | L7: =K7/E5 -> 9.7803043e-06 | M7: =ROUNDDOWN(L7*E6,0) -> 1 | N7: 147059 | O7: =N7/K7 -> 2262.4462 | P7: =M7*O7 -> 2262.4462
B8: https://www.ic3.gov/Media/PDF/AnnualReport/2016State/StateReport.aspx#?s=47 | C8: Business Email Compromise | D8: State Victim Count | E8: 161 | F8: =E8/E5 -> 2.4225061e-05 | G8: =ROUNDDOWN(F8*E6,0) -> 4 | H8: 2781785 | I8: =H8/E8 -> 17278.168 | J8: =I8*G8 -> 69112.671 | K8: 43 | L8: =K8/E5 -> 6.4700474e-06 | M8: =ROUNDDOWN(L8*E6,0) -> 1 | N8: 546991 | O8: =N8/K8 -> 12720.721 | P8: =M8*O8 -> 12720.721
B9: https://www.ic3.gov/Media/PDF/AnnualReport/2016State/StateReport.aspx#?s=47 | C9: Botnet | D9: State Victim Count | F9: =E9/E5 -> 0 | G9: =ROUNDDOWN(F9*E6,0) -> 0 | I9: =H9/E9 -> #DIV/0! | J9: =I9*G9 -> #DIV/0! | L9: =K9/E5 -> 0 | M9: =ROUNDDOWN(L9*E6,0) -> 0 | O9: =N9/K9 -> #DIV/0! | P9: =M9*O9 -> #DIV/0!
B10: https://www.ic3.gov/Media/PDF/AnnualReport/2016State/StateReport.aspx#?s=47 | C10: Confidence/Romance | D10: State Victim Count | E10: 220 | F10: =E10/E5 -> 3.3102568e-05 | G10: =ROUNDDOWN(F10*E6,0) -> 5 | H10: 2251140 | I10: =H10/E10 -> 10232.455 | J10: =I10*G10 -> 51162.273 | K10: 74 | L10: =K10/E5 -> 1.11345e-05 | M10: =ROUNDDOWN(L10*E6,0) -> 1 | N10: 955402 | O10: =N10/K10 -> 12910.838 | P10: =M10*O10 -> 12910.838
B11: https://www.ic3.gov/Media/PDF/AnnualReport/2016State/StateReport.aspx#?s=47 | C11: Check Fraud | D11: State Victim Count | F11: =E11/E5 -> 0 | G11: =ROUNDDOWN(F11*E6,0) -> 0 | I11: =H11/E11 -> #DIV/0! | J11: =I11*G11 -> #DIV/0! | L11: =K11/E5 -> 0 | M11: =ROUNDDOWN(L11*E6,0) -> 0 | O11: =N11/K11 -> #DIV/0! | P11: =M11*O11 -> #DIV/0!
B12: https://www.ic3.gov/Media/PDF/AnnualReport/2016State/StateReport.aspx#?s=47 | C12: Crimes Against Children | D12: State Victim Count | E12: 14 | F12: =E12/E5 -> 2.1065271e-06 | G12: =ROUNDDOWN(F12*E6,0) -> 0 | H12: 175 | I12: =H12/E12 -> 12.5 | J12: =I12*G12 -> 0 | K12: 5 | L12: =K12/E5 -> 7.523311e-07 | M12: =ROUNDDOWN(L12*E6,0) -> 0 | N12: 0 | O12: =N12/K12 -> 0 | P12: =M12*O12 -> 0
B13: https://www.ic3.gov/Media/PDF/AnnualReport/2016State/StateReport.aspx#?s=47 | C13: Data Breach | D13: State Victim Count | E13: 53 | F13: =E13/E5 -> 7.9747096e-06 | G13: =ROUNDDOWN(F13*E6,0) -> 1 | H13: 121715 | I13: =H13/E13 -> 2296.5094 | J13: =I13*G13 -> 2296.5094 | K13: 11 | L13: =K13/E5 -> 1.6551284e-06 | M13: =ROUNDDOWN(L13*E6,0) -> 0 | N13: 35450 | P13: =M13*O13 -> 0
B14: https://www.ic3.gov/Media/PDF/AnnualReport/2016State/StateReport.aspx#?s=47 | C14: Employment | D14: State Victim Count | E14: 271 | F14: =E14/E5 -> 4.0776346e-05 | G14: =ROUNDDOWN(F14*E6,0) -> 7 | H14: 513855 | I14: =H14/E14 -> 1896.1439 | J14: =I14*G14 -> 13273.007 | K14: 75 | L14: =K14/E5 -> 1.1284966e-05 | M14: =ROUNDDOWN(L14*E6,0) -> 2 | N14: 111690 | O14: =N14/K14 -> 1489.2 | P14: =M14*O14 -> 2978.4
B15: https://www.ic3.gov/Media/PDF/AnnualReport/2016State/StateReport.aspx#?s=47 | C15: Extortion | D15: State Victim Count | E15: 361 | F15: =E15/E5 -> 5.4318305e-05 | G15: =ROUNDDOWN(F15*E6,0) -> 9 | H15: 249043 | I15: =H15/E15 -> 689.86981 | J15: =I15*G15 -> 6208.8283 | K15: 38 | L15: =K15/E5 -> 5.7177163e-06 | M15: =ROUNDDOWN(L15*E6,0) -> 1 | N15: 54046 | O15: =N15/K15 -> 1422.2632 | P15: =M15*O15 -> 1422.2632
B16: https://www.ic3.gov/Media/PDF/AnnualReport/2016State/StateReport.aspx#?s=47 | C16: Government Impersonation | D16: State Victim Count | E16: 291 | F16: =E16/E5 -> 4.378567e-05 | G16: =ROUNDDOWN(F16*E6,0) -> 7 | H16: 200649 | J16: =I16*G16 -> 0 | K16: 20 | L16: =K16/E5 -> 3.0093244e-06 | M16: =ROUNDDOWN(L16*E6,0) -> 0 | N16: 12891 | O16: =N16/K16 -> 644.55 | P16: =M16*O16 -> 0
B17: https://www.ic3.gov/Media/PDF/AnnualReport/2016State/StateReport.aspx#?s=47 | C17: Harassing/Stalking | D17: State Victim Count | F17: =E17/E5 -> 0 | G17: =ROUNDDOWN(F17*E6,0) -> 0 | I17: =H17/E17 -> #DIV/0! | J17: =I17*G17 -> #DIV/0! | L17: =K17/E5 -> 0 | M17: =ROUNDDOWN(L17*E6,0) -> 0 | O17: =N17/K17 -> #DIV/0! | P17: =M17*O17 -> #DIV/0!
B18: https://www.ic3.gov/Media/PDF/AnnualReport/2016State/StateReport.aspx#?s=47 | C18: IPR/Counterfeit | D18: State Victim Count | E18: 44 | F18: =E18/E5 -> 6.6205137e-06 | G18: =ROUNDDOWN(F18*E6,0) -> 1 | H18: 31909 | I18: =H18/E18 -> 725.20455 | J18: =I18*G18 -> 725.20455 | K18: 13 | L18: =K18/E5 -> 1.9560609e-06 | M18: =ROUNDDOWN(L18*E6,0) -> 0 | N18: 6030 | O18: =N18/K18 -> 463.84615 | P18: =M18*O18 -> 0
B19: https://www.ic3.gov/Media/PDF/AnnualReport/2016State/StateReport.aspx#?s=47 | C19: Identity Theft | D19: State Victim Count | E19: 281 | F19: =E19/E5 -> 4.2281008e-05 | G19: =ROUNDDOWN(F19*E6,0) -> 7 | H19: 564262 | I19: =H19/E19 -> 2008.0498 | J19: =I19*G19 -> 14056.349 | K19: 77 | L19: =K19/E5 -> 1.1585899e-05 | M19: =ROUNDDOWN(L19*E6,0) -> 2 | N19: 248422 | O19: =N19/K19 -> 3226.2597 | P19: =M19*O19 -> 6452.5195
B20: https://www.ic3.gov/Media/PDF/AnnualReport/2016State/StateReport.aspx#?s=47 | C20: Investment | D20: State Victim Count | E20: 15 | F20: =E20/E5 -> 2.2569933e-06 | G20: =ROUNDDOWN(F20*E6,0) -> 0 | H20: 604540 | I20: =H20/E20 -> 40302.667 | J20: =I20*G20 -> 0 | K20: 10 | L20: =K20/E5 -> 1.5046622e-06 | M20: =ROUNDDOWN(L20*E6,0) -> 0 | N20: 377812 | O20: =N20/K20 -> 37781.2 | P20: =M20*O20 -> 0
B21: https://www.ic3.gov/Media/PDF/AnnualReport/2016State/StateReport.aspx#?s=47 | C21: Lottery/Sweepstakes/Inheritance | D21: State Victim Count | E21: 102 | F21: =E21/E5 -> 1.5347554e-05 | G21: =ROUNDDOWN(F21*E6,0) -> 2 | H21: 780297 | I21: =H21/E21 -> 7649.9706 | J21: =I21*G21 -> 15299.941 | K21: 17 | L21: =K21/E5 -> 2.5579257e-06 | M21: =ROUNDDOWN(L21*E6,0) -> 0 | N21: 87613 | O21: =N21/K21 -> 5153.7059 | P21: =M21*O21 -> 0
B22: https://www.ic3.gov/Media/PDF/AnnualReport/2016State/StateReport.aspx#?s=47 | C22: Malware | D22: State Victim Count | E22: 60 | F22: =E22/E5 -> 9.0279732e-06 | G22: =ROUNDDOWN(F22*E6,0) -> 1 | H22: =8139+7793 -> 15932 | I22: =H22/E22 -> 265.53333 | J22: =I22*G22 -> 265.53333 | K22: 14 | L22: =K22/E5 -> 2.1065271e-06 | M22: =ROUNDDOWN(L22*E6,0) -> 0 | N22: 517 | O22: =N22/K22 -> 36.928571 | P22: =M22*O22 -> 0
B23: https://www.ic3.gov/Media/PDF/AnnualReport/2016State/StateReport.aspx#?s=47 | C23: NCDF | D23: State Victim Count | F23: =E23/E5 -> 0 | G23: =ROUNDDOWN(F23*E6,0) -> 0 | I23: =H23/E23 -> #DIV/0! | J23: =I23*G23 -> #DIV/0! | L23: =K23/E5 -> 0 | M23: =ROUNDDOWN(L23*E6,0) -> 0 | O23: =N23/K23 -> #DIV/0! | P23: =M23*O23 -> #DIV/0!
B24: https://www.ic3.gov/Media/PDF/AnnualReport/2016State/StateReport.aspx#?s=47 | C24: NTOC | D24: State Victim Count | F24: =E24/E5 -> 0 | G24: =ROUNDDOWN(F24*E6,0) -> 0 | I24: =H24/E24 -> #DIV/0! | J24: =I24*G24 -> #DIV/0! | L24: =K24/E5 -> 0 | M24: =ROUNDDOWN(L24*E6,0) -> 0 | O24: =N24/K24 -> #DIV/0! | P24: =M24*O24 -> #DIV/0!
B25: https://www.ic3.gov/Media/PDF/AnnualReport/2016State/StateReport.aspx#?s=47 | C25: No Lead Value | D25: State Victim Count | E25: 146 | F25: =E25/E5 -> 2.1968068e-05 | G25: =ROUNDDOWN(F25*E6,0) -> 3 | H25: 0 | I25: =H25/E25 -> 0 | J25: =I25*G25 -> 0 | K25: 215 | L25: =K25/E5 -> 3.2350237e-05 | M25: =ROUNDDOWN(L25*E6,0) -> 5 | N25: 0 | O25: =N25/K25 -> 0 | P25: =M25*O25 -> 0
B26: https://www.ic3.gov/Media/PDF/AnnualReport/2016State/StateReport.aspx#?s=47 | C26: Non-Payable/Non-Delivery | D26: State Victim Count | E26: 1285 | F26: =E26/E5 -> 0.00019334909 | G26: =ROUNDDOWN(F26*E6,0) -> 34 | H26: 1996281 | I26: =H26/E26 -> 1553.5261 | J26: =I26*G26 -> 52819.886 | K26: 495 | L26: =K26/E5 -> 7.4480779e-05 | M26: =ROUNDDOWN(L26*E6,0) -> 13 | N26: 1547162 | O26: =N26/K26 -> 3125.5798 | P26: =M26*O26 -> 40632.537
B27: https://www.ic3.gov/Media/PDF/AnnualReport/2016State/StateReport.aspx#?s=47 | C27: Other | D27: State Victim Count | E27: 148 | F27: =E27/E5 -> 2.2269e-05 | G27: =ROUNDDOWN(F27*E6,0) -> 3 | H27: 421656 | I27: =H27/E27 -> 2849.027 | J27: =I27*G27 -> 8547.0811 | K27: 45 | L27: =K27/E5 -> 6.7709799e-06 | M27: =ROUNDDOWN(L27*E6,0) -> 1 | N27: 180005 | O27: =N27/K27 -> 4000.1111 | P27: =M27*O27 -> 4000.1111
B28: https://www.ic3.gov/Media/PDF/AnnualReport/2016State/StateReport.aspx#?s=47 | C28: Overpayment | D28: State Victim Count | F28: =E28/E5 -> 0 | G28: =ROUNDDOWN(F28*E6,0) -> 0 | H28: NO MATCH | I28: =H28/E28 -> #VALUE! | J28: =I28*G28 -> #VALUE! | L28: =K28/E5 -> 0 | M28: =ROUNDDOWN(L28*E6,0) -> 0 | O28: =N28/K28 -> #DIV/0! | P28: =M28*O28 -> #DIV/0!
B29: https://www.ic3.gov/Media/PDF/AnnualReport/2016State/StateReport.aspx#?s=47 | C29: Personal Data Breach | D29: State Victim Count | E29: 429 | F29: =E29/E5 -> 6.4550008e-05 | G29: =ROUNDDOWN(F29*E6,0) -> 11 | H29: 938982 | I29: =H29/E29 -> 2188.7692 | J29: =I29*G29 -> 24076.462 | K29: 282 | L29: =K29/E5 -> 4.2431474e-05 | M29: =ROUNDDOWN(L29*E6,0) -> 7 | N29: 97512 | O29: =N29/K29 -> 345.78723 | P29: =M29*O29 -> 2420.5106
B30: https://www.ic3.gov/Media/PDF/AnnualReport/2016State/StateReport.aspx#?s=47 | C30: Phishing | D30: State Victim Count | E30: 298 | F30: =E30/E5 -> 4.4838933e-05 | G30: =ROUNDDOWN(F30*E6,0) -> 7 | H30: 267275 | I30: =H30/E30 -> 896.89597 | J30: =I30*G30 -> 6278.2718 | K30: 36 | L30: =K30/E5 -> 5.4167839e-06 | M30: =ROUNDDOWN(L30*E6,0) -> 0 | N30: 9790 | O30: =N30/K30 -> 271.94444 | P30: =M30*O30 -> 0
B31: https://www.ic3.gov/Media/PDF/AnnualReport/2016State/StateReport.aspx#?s=47 | C31: Ransomware | D31: State Victim Count | E31: 49 | F31: =E31/E5 -> 7.3728448e-06 | G31: =ROUNDDOWN(F31*E6,0) -> 1 | H31: 10106 | I31: =H31/E31 -> 206.2449 | J31: =I31*G31 -> 206.2449 | K31: 3 | L31: =K31/E5 -> 4.5139866e-07 | M31: =ROUNDDOWN(L31*E6,0) -> 0 | N31: 0 | O31: =N31/K31 -> 0 | P31: =M31*O31 -> 0
B32: https://www.ic3.gov/Media/PDF/AnnualReport/2016State/StateReport.aspx#?s=47 | C32: Real Estate | D32: State Victim Count | E32: 165 | F32: =E32/E5 -> 2.4826926e-05 | G32: =ROUNDDOWN(F32*E6,0) -> 4 | H32: 528855 | I32: =H32/E32 -> 3205.1818 | J32: =I32*G32 -> 12820.727 | K32: 78 | L32: =K32/E5 -> 1.1736365e-05 | M32: =ROUNDDOWN(L32*E6,0) -> 2 | N32: 459938 | O32: =N32/K32 -> 5896.641 | P32: =M32*O32 -> 11793.282
B33: https://www.ic3.gov/Media/PDF/AnnualReport/2016State/StateReport.aspx#?s=47 | C33: SIM Swap | D33: State Victim Count | F33: =E33/E5 -> 0 | G33: =ROUNDDOWN(F33*E6,0) -> 0 | H33: NO MATCH | I33: =H33/E33 -> #VALUE! | J33: =I33*G33 -> #VALUE! | L33: =K33/E5 -> 0 | M33: =ROUNDDOWN(L33*E6,0) -> 0 | O33: =N33/K33 -> #DIV/0! | P33: =M33*O33 -> #DIV/0!
B34: https://www.ic3.gov/Media/PDF/AnnualReport/2016State/StateReport.aspx#?s=47 | C34: Spoofing | D34: State Victim Count | F34: =E34/E5 -> 0 | G34: =ROUNDDOWN(F34*E6,0) -> 0 | H34: NO MATCH | I34: =H34/E34 -> #VALUE! | J34: =I34*G34 -> #VALUE! | K34: 11 | L34: =K34/E5 -> 1.6551284e-06 | M34: =ROUNDDOWN(L34*E6,0) -> 0 | O34: =N34/K34 -> 0 | P34: =M34*O34 -> 0
B35: https://www.ic3.gov/Media/PDF/AnnualReport/2016State/StateReport.aspx#?s=47 | C35: Tech Support | D35: State Victim Count | E35: 185 | F35: =E35/E5 -> 2.7836251e-05 | G35: =ROUNDDOWN(F35*E6,0) -> 4 | H35: 131727 | I35: =H35/E35 -> 712.03784 | J35: =I35*G35 -> 2848.1514 | L35: =K35/E5 -> 0 | M35: =ROUNDDOWN(L35*E6,0) -> 0 | N35: 2750 | O35: =N35/K35 -> #DIV/0! | P35: =M35*O35 -> #DIV/0!
B36: https://www.ic3.gov/Media/PDF/AnnualReport/2016State/StateReport.aspx#?s=47 | C36: Threats of Violence | D36: State Victim Count | E36: 276 | F36: =E36/E5 -> 4.1528677e-05 | G36: =ROUNDDOWN(F36*E6,0) -> 7 | H36: 227858 | I36: =H36/E36 -> 825.57246 | J36: =I36*G36 -> 5779.0072 | K36: 283 | L36: =K36/E5 -> 4.258194e-05 | M36: =ROUNDDOWN(L36*E6,0) -> 7 | N36: 57874 | O36: =N36/K36 -> 204.50177 | P36: =M36*O36 -> 1431.5124
J37: =I37*G37 -> 0
E38: =SUM(E7:E36) -> 5130 | G38: =SUM(G8:G36) -> 118 | I38: =H38/E38 -> 0 | J38: =I38*G38 -> 0
C39: Malware + Virus
C40: Harassment, Stalking, Threats of Violence and Terrorism all combined

Sheet 2017_IC3 State to City
B4: REF URL | C4: Decription | D4: Unit | E4: Value | F4: Value/State Population | G4: Estimated In-City Victims, 2022, As if IC3 Victim Complaint | H4: State Victim Loss | I4: Even Loss per State Victim Count | J4: Projected In-City Victim Loss | K4: State Subject (Perpetrator) Count | L4: Subject (Perpetrator) to State Population | M4: Estimated Subject to City Population | N4: State Subject Losses (Perpetrator gained X dollars) | O4: Even Loss per State Subject | P4: Estimated In-City Subject Losses (Perpetrator Take from Victim)
B5: https://www.census.gov/quickfacts/fact/table/TN/PST045222 | C5: TN Population in 2017 | D5: Population Estimate | E5: 6708799 | F5: Raw Value | G5: (Victim Count/State Population ) * City Population | J5: Estimated In-City Victims * Even Loss per State Victim | P5: Subject to City * Even Loss per State Subject
B6: https://www.census.gov/quickfacts/chattanoogacitytennessee | C6: Chattanooga Population in 2017 | D6: Population Estimate | E6: 179530
B7: https://www.ic3.gov/Media/PDF/AnnualReport/2017State/StateReport.aspx#?s=47 | C7: Advanced Fee | D7: State Victim Count | E7: 264 | F7: =E7/E5 -> 3.9351306e-05 | G7: =ROUNDDOWN(F7*E6,0) -> 7 | H7: 591748 | I7: =H7/E7 -> 2241.4697 | J7: =I7*G7 -> 15690.288 | K7: 70 | L7: =K7/E5 -> 1.0434058e-05 | M7: =ROUNDDOWN(L7*E6,0) -> 1 | N7: 222720 | O7: =N7/K7 -> 3181.7143 | P7: =M7*O7 -> 3181.7143
B8: https://www.ic3.gov/Media/PDF/AnnualReport/2017State/StateReport.aspx#?s=47 | C8: Business Email Compromise | D8: State Victim Count | E8: 184 | F8: =E8/E5 -> 2.7426668e-05 | G8: =ROUNDDOWN(F8*E6,0) -> 4 | H8: 4251983 | I8: =H8/E8 -> 23108.603 | J8: =I8*G8 -> 92434.413 | K8: 44 | L8: =K8/E5 -> 6.5585509e-06 | M8: =ROUNDDOWN(L8*E6,0) -> 1 | N8: 577018 | O8: =N8/K8 -> 13114.045 | P8: =M8*O8 -> 13114.045
B9: https://www.ic3.gov/Media/PDF/AnnualReport/2017State/StateReport.aspx#?s=47 | C9: Botnet | D9: State Victim Count | F9: =E9/E5 -> 0 | G9: =ROUNDDOWN(F9*E6,0) -> 0 | I9: =H9/E9 -> #DIV/0! | J9: =I9*G9 -> #DIV/0! | L9: =K9/E5 -> 0 | M9: =ROUNDDOWN(L9*E6,0) -> 0 | O9: =N9/K9 -> #DIV/0! | P9: =M9*O9 -> #DIV/0!
B10: https://www.ic3.gov/Media/PDF/AnnualReport/2017State/StateReport.aspx#?s=47 | C10: Confidence/Romance | D10: State Victim Count | E10: 260 | F10: =E10/E5 -> 3.8755074e-05 | G10: =ROUNDDOWN(F10*E6,0) -> 6 | H10: 2450680 | I10: =H10/E10 -> 9425.6923 | J10: =I10*G10 -> 56554.154 | K10: 88 | L10: =K10/E5 -> 1.3117102e-05 | M10: =ROUNDDOWN(L10*E6,0) -> 2 | N10: 682875 | O10: =N10/K10 -> 7759.9432 | P10: =M10*O10 -> 15519.886
B11: https://www.ic3.gov/Media/PDF/AnnualReport/2017State/StateReport.aspx#?s=47 | C11: Check Fraud | D11: State Victim Count | F11: =E11/E5 -> 0 | G11: =ROUNDDOWN(F11*E6,0) -> 0 | I11: =H11/E11 -> #DIV/0! | J11: =I11*G11 -> #DIV/0! | L11: =K11/E5 -> 0 | M11: =ROUNDDOWN(L11*E6,0) -> 0 | O11: =N11/K11 -> #DIV/0! | P11: =M11*O11 -> #DIV/0!
B12: https://www.ic3.gov/Media/PDF/AnnualReport/2017State/StateReport.aspx#?s=47 | C12: Crimes Against Children | D12: State Victim Count | E12: 19 | F12: =E12/E5 -> 2.8321015e-06 | G12: =ROUNDDOWN(F12*E6,0) -> 0 | H12: 0 | I12: =H12/E12 -> 0 | J12: =I12*G12 -> 0 | K12: 3 | L12: =K12/E5 -> 4.4717393e-07 | M12: =ROUNDDOWN(L12*E6,0) -> 0 | N12: 0 | O12: =N12/K12 -> 0 | P12: =M12*O12 -> 0
B13: https://www.ic3.gov/Media/PDF/AnnualReport/2017State/StateReport.aspx#?s=47 | C13: Data Breach | D13: State Victim Count | E13: 53 | F13: =E13/E5 -> 7.9000727e-06 | G13: =ROUNDDOWN(F13*E6,0) -> 1 | H13: 967932 | I13: =H13/E13 -> 18262.868 | J13: =I13*G13 -> 18262.868 | K13: 6 | L13: =K13/E5 -> 8.9434786e-07 | M13: =ROUNDDOWN(L13*E6,0) -> 0 | N13: 0 | O13: =N13/K13 -> 0 | P13: =M13*O13 -> 0
B14: https://www.ic3.gov/Media/PDF/AnnualReport/2017State/StateReport.aspx#?s=47 | C14: Employment | D14: State Victim Count | E14: 257 | F14: =E14/E5 -> 3.83079e-05 | G14: =ROUNDDOWN(F14*E6,0) -> 6 | H14: 346353 | I14: =H14/E14 -> 1347.677 | J14: =I14*G14 -> 8086.0623 | K14: 76 | L14: =K14/E5 -> 1.1328406e-05 | M14: =ROUNDDOWN(L14*E6,0) -> 2 | N14: 49381 | O14: =N14/K14 -> 649.75 | P14: =M14*O14 -> 1299.5
B15: https://www.ic3.gov/Media/PDF/AnnualReport/2017State/StateReport.aspx#?s=47 | C15: Extortion | D15: State Victim Count | E15: 290 | F15: =E15/E5 -> 4.3226813e-05 | G15: =ROUNDDOWN(F15*E6,0) -> 7 | H15: 171336 | I15: =H15/E15 -> 590.81379 | J15: =I15*G15 -> 4135.6966 | K15: 32 | L15: =K15/E5 -> 4.7698552e-06 | M15: =ROUNDDOWN(L15*E6,0) -> 0 | N15: 10895 | O15: =N15/K15 -> 340.46875 | P15: =M15*O15 -> 0
B16: https://www.ic3.gov/Media/PDF/AnnualReport/2017State/StateReport.aspx#?s=47 | C16: Government Impersonation | D16: State Victim Count | E16: 174 | F16: =E16/E5 -> 2.5936088e-05 | G16: =ROUNDDOWN(F16*E6,0) -> 4 | H16: 118043 | I16: =H16/E16 -> 678.40805 | J16: =I16*G16 -> 2713.6322 | K16: 11 | L16: =K16/E5 -> 1.6396377e-06 | M16: =ROUNDDOWN(L16*E6,0) -> 0 | N16: 17516 | O16: =N16/K16 -> 1592.3636 | P16: =M16*O16 -> 0
B17: https://www.ic3.gov/Media/PDF/AnnualReport/2017State/StateReport.aspx#?s=47 | C17: Harassing/Stalking | D17: State Victim Count | F17: =E17/E5 -> 0 | G17: =ROUNDDOWN(F17*E6,0) -> 0 | I17: =H17/E17 -> #DIV/0! | J17: =I17*G17 -> #DIV/0! | L17: =K17/E5 -> 0 | M17: =ROUNDDOWN(L17*E6,0) -> 0 | O17: =N17/K17 -> #DIV/0! | P17: =M17*O17 -> #DIV/0!
B18: https://www.ic3.gov/Media/PDF/AnnualReport/2017State/StateReport.aspx#?s=47 | C18: IPR/Counterfeit | D18: State Victim Count | E18: 38 | F18: =E18/E5 -> 5.6642031e-06 | G18: =ROUNDDOWN(F18*E6,0) -> 1 | H18: 34455 | I18: =H18/E18 -> 906.71053 | J18: =I18*G18 -> 906.71053 | K18: 12 | L18: =K18/E5 -> 1.7886957e-06 | M18: =ROUNDDOWN(L18*E6,0) -> 0 | N18: 8398 | O18: =N18/K18 -> 699.83333 | P18: =M18*O18 -> 0
B19: https://www.ic3.gov/Media/PDF/AnnualReport/2017State/StateReport.aspx#?s=47 | C19: Identity Theft | D19: State Victim Count | E19: 332 | F19: =E19/E5 -> 4.9487248e-05 | G19: =ROUNDDOWN(F19*E6,0) -> 8 | H19: 1241184 | I19: =H19/E19 -> 3738.506 | J19: =I19*G19 -> 29908.048 | K19: 98 | L19: =K19/E5 -> 1.4607682e-05 | M19: =ROUNDDOWN(L19*E6,0) -> 2 | N19: 677427 | O19: =N19/K19 -> 6912.5204 | P19: =M19*O19 -> 13825.041
B20: https://www.ic3.gov/Media/PDF/AnnualReport/2017State/StateReport.aspx#?s=47 | C20: Investment | D20: State Victim Count | E20: 34 | F20: =E20/E5 -> 5.0679712e-06 | G20: =ROUNDDOWN(F20*E6,0) -> 0 | H20: 260468 | I20: =H20/E20 -> 7660.8235 | J20: =I20*G20 -> 0 | K20: 16 | L20: =K20/E5 -> 2.3849276e-06 | M20: =ROUNDDOWN(L20*E6,0) -> 0 | N20: 143560 | O20: =N20/K20 -> 8972.5 | P20: =M20*O20 -> 0
B21: https://www.ic3.gov/Media/PDF/AnnualReport/2017State/StateReport.aspx#?s=47 | C21: Lottery/Sweepstakes/Inheritance | D21: State Victim Count | E21: 77 | F21: =E21/E5 -> 1.1477464e-05 | G21: =ROUNDDOWN(F21*E6,0) -> 2 | H21: 121151 | I21: =H21/E21 -> 1573.3896 | J21: =I21*G21 -> 3146.7792 | K21: 21 | L21: =K21/E5 -> 3.1302175e-06 | M21: =ROUNDDOWN(L21*E6,0) -> 0 | N21: 83881 | O21: =N21/K21 -> 3994.3333 | P21: =M21*O21 -> 0
B22: https://www.ic3.gov/Media/PDF/AnnualReport/2017State/StateReport.aspx#?s=47 | C22: Malware | D22: State Victim Count | E22: 43 | F22: =E22/E5 -> 6.409493e-06 | G22: =ROUNDDOWN(F22*E6,0) -> 1 | H22: 13325 | I22: =H22/E22 -> 309.88372 | J22: =I22*G22 -> 309.88372 | K22: 5 | L22: =K22/E5 -> 7.4528988e-07 | M22: =ROUNDDOWN(L22*E6,0) -> 0 | N22: 1033 | O22: =N22/K22 -> 206.6 | P22: =M22*O22 -> 0
B23: https://www.ic3.gov/Media/PDF/AnnualReport/2017State/StateReport.aspx#?s=47 | C23: NCDF | D23: State Victim Count | F23: =E23/E5 -> 0 | G23: =ROUNDDOWN(F23*E6,0) -> 0 | I23: =H23/E23 -> #DIV/0! | J23: =I23*G23 -> #DIV/0! | L23: =K23/E5 -> 0 | M23: =ROUNDDOWN(L23*E6,0) -> 0 | O23: =N23/K23 -> #DIV/0! | P23: =M23*O23 -> #DIV/0!
B24: https://www.ic3.gov/Media/PDF/AnnualReport/2017State/StateReport.aspx#?s=47 | C24: NTOC | D24: State Victim Count | F24: =E24/E5 -> 0 | G24: =ROUNDDOWN(F24*E6,0) -> 0 | I24: =H24/E24 -> #DIV/0! | J24: =I24*G24 -> #DIV/0! | L24: =K24/E5 -> 0 | M24: =ROUNDDOWN(L24*E6,0) -> 0 | O24: =N24/K24 -> #DIV/0! | P24: =M24*O24 -> #DIV/0!
B25: https://www.ic3.gov/Media/PDF/AnnualReport/2017State/StateReport.aspx#?s=47 | C25: No Lead Value | D25: State Victim Count | E25: 155 | F25: =E25/E5 -> 2.3103986e-05 | G25: =ROUNDDOWN(F25*E6,0) -> 4 | H25: 0 | I25: =H25/E25 -> 0 | J25: =I25*G25 -> 0 | K25: 157 | L25: =K25/E5 -> 2.3402102e-05 | M25: =ROUNDDOWN(L25*E6,0) -> 4 | N25: 0 | O25: =N25/K25 -> 0 | P25: =M25*O25 -> 0
B26: https://www.ic3.gov/Media/PDF/AnnualReport/2017State/StateReport.aspx#?s=47 | C26: Non-Payable/Non-Delivery | D26: State Victim Count | E26: 1547 | F26: =E26/E5 -> 0.00023059269 | G26: =ROUNDDOWN(F26*E6,0) -> 41 | H26: 2217462 | I26: =H26/E26 -> 1433.395 | J26: =I26*G26 -> 58769.193 | K26: 480 | L26: =K26/E5 -> 7.1547828e-05 | M26: =ROUNDDOWN(L26*E6,0) -> 12 | N26: 906871 | O26: =N26/K26 -> 1889.3146 | P26: =M26*O26 -> 22671.775
B27: https://www.ic3.gov/Media/PDF/AnnualReport/2017State/StateReport.aspx#?s=47 | C27: Other | D27: State Victim Count | E27: 207 | F27: =E27/E5 -> 3.0855001e-05 | G27: =ROUNDDOWN(F27*E6,0) -> 5 | H27: 297647 | I27: =H27/E27 -> 1437.9082 | J27: =I27*G27 -> 7189.5411 | K27: 68 | L27: =K27/E5 -> 1.0135942e-05 | M27: =ROUNDDOWN(L27*E6,0) -> 1 | N27: 6964 | O27: =N27/K27 -> 102.41176 | P27: =M27*O27 -> 102.41176
B28: https://www.ic3.gov/Media/PDF/AnnualReport/2017State/StateReport.aspx#?s=47 | C28: Overpayment | D28: State Victim Count | E28: 321 | F28: =E28/E5 -> 4.784761e-05 | G28: =ROUNDDOWN(F28*E6,0) -> 8 | H28: 702742 | I28: =H28/E28 -> 2189.2274 | J28: =I28*G28 -> 17513.819 | K28: 86 | L28: =K28/E5 -> 1.2818986e-05 | M28: =ROUNDDOWN(L28*E6,0) -> 2 | N28: 92394 | O28: =N28/K28 -> 1074.3488 | P28: =M28*O28 -> 2148.6977
B29: https://www.ic3.gov/Media/PDF/AnnualReport/2017State/StateReport.aspx#?s=47 | C29: Personal Data Breach | D29: State Victim Count | E29: 490 | F29: =E29/E5 -> 7.3038408e-05 | G29: =ROUNDDOWN(F29*E6,0) -> 13 | H29: 461249 | I29: =H29/E29 -> 941.32449 | J29: =I29*G29 -> 12237.218 | K29: 132 | L29: =K29/E5 -> 1.9675653e-05 | M29: =ROUNDDOWN(L29*E6,0) -> 3 | N29: 180877 | O29: =N29/K29 -> 1370.2803 | P29: =M29*O29 -> 4110.8409
B30: https://www.ic3.gov/Media/PDF/AnnualReport/2017State/StateReport.aspx#?s=47 | C30: Phishing | D30: State Victim Count | E30: 347 | F30: =E30/E5 -> 5.1723118e-05 | G30: =ROUNDDOWN(F30*E6,0) -> 9 | H30: 133594 | I30: =H30/E30 -> 384.99712 | J30: =I30*G30 -> 3464.9741 | K30: 57 | L30: =K30/E5 -> 8.4963046e-06 | M30: =ROUNDDOWN(L30*E6,0) -> 1 | N30: 18601 | O30: =N30/K30 -> 326.33333 | P30: =M30*O30 -> 326.33333
B31: https://www.ic3.gov/Media/PDF/AnnualReport/2017State/StateReport.aspx#?s=47 | C31: Ransomware | D31: State Victim Count | E31: 33 | F31: =E31/E5 -> 4.9189132e-06 | G31: =ROUNDDOWN(F31*E6,0) -> 0 | H31: 95411 | I31: =H31/E31 -> 2891.2424 | J31: =I31*G31 -> 0 | K31: 2 | L31: =K31/E5 -> 2.9811595e-07 | M31: =ROUNDDOWN(L31*E6,0) -> 0 | N31: 50000 | O31: =N31/K31 -> 25000 | P31: =M31*O31 -> 0
B32: https://www.ic3.gov/Media/PDF/AnnualReport/2017State/StateReport.aspx#?s=47 | C32: Real Estate | D32: State Victim Count | E32: 148 | F32: =E32/E5 -> 2.206058e-05 | G32: =ROUNDDOWN(F32*E6,0) -> 3 | H32: 262428 | I32: =H32/E32 -> 1773.1622 | J32: =I32*G32 -> 5319.4865 | K32: 78 | L32: =K32/E5 -> 1.1626522e-05 | M32: =ROUNDDOWN(L32*E6,0) -> 2 | N32: 454840 | O32: =N32/K32 -> 5831.2821 | P32: =M32*O32 -> 11662.564
B33: https://www.ic3.gov/Media/PDF/AnnualReport/2017State/StateReport.aspx#?s=47 | C33: SIM Swap | D33: State Victim Count | F33: =E33/E5 -> 0 | G33: =ROUNDDOWN(F33*E6,0) -> 0 | I33: =H33/E33 -> #DIV/0! | J33: =I33*G33 -> #DIV/0! | L33: =K33/E5 -> 0 | M33: =ROUNDDOWN(L33*E6,0) -> 0 | O33: =N33/K33 -> #DIV/0! | P33: =M33*O33 -> #DIV/0!
B34: https://www.ic3.gov/Media/PDF/AnnualReport/2017State/StateReport.aspx#?s=47 | C34: Spoofing | D34: State Victim Count | E34: 0 | F34: =E34/E5 -> 0 | G34: =ROUNDDOWN(F34*E6,0) -> 0 | H34: 0 | I34: =H34/E34 -> #DIV/0! | J34: =I34*G34 -> #DIV/0! | K34: 0 | L34: =K34/E5 -> 0 | M34: =ROUNDDOWN(L34*E6,0) -> 0 | N34: 0 | O34: =N34/K34 -> #DIV/0! | P34: =M34*O34 -> #DIV/0!
B35: https://www.ic3.gov/Media/PDF/AnnualReport/2017State/StateReport.aspx#?s=47 | C35: Tech Support | D35: State Victim Count | E35: 190 | F35: =E35/E5 -> 2.8321015e-05 | G35: =ROUNDDOWN(F35*E6,0) -> 5 | H35: 168911 | I35: =H35/E35 -> 889.00526 | J35: =I35*G35 -> 4445.0263 | K35: 14 | L35: =K35/E5 -> 2.0868117e-06 | M35: =ROUNDDOWN(L35*E6,0) -> 0 | N35: 8331 | O35: =N35/K35 -> 595.07143 | P35: =M35*O35 -> 0
B36: https://www.ic3.gov/Media/PDF/AnnualReport/2017State/StateReport.aspx#?s=47 | C36: Threats of Violence | D36: State Victim Count | E36: 230 | F36: =E36/E5 -> 3.4283334e-05 | G36: =ROUNDDOWN(F36*E6,0) -> 6 | H36: 96901 | I36: =H36/E36 -> 421.3087 | J36: =I36*G36 -> 2527.8522 | K36: 112 | L36: =K36/E5 -> 1.6694493e-05 | M36: =ROUNDDOWN(L36*E6,0) -> 2 | N36: 98776 | O36: =N36/K36 -> 881.92857 | P36: =M36*O36 -> 1763.8571
J37: =I37*G37 -> 0
E38: =SUM(E7:E36) -> 5693 | G38: =SUM(G8:G36) -> 134 | I38: =H38/E38 -> 0 | J38: =I38*G38 -> 0
C40: Harassment, Stalking, Threats of Violence and Terrorism all combined
C41: Had 2 Terrorism this year

Sheet 2018_IC3 State to City
B4: REF URL | C4: Decription | D4: Unit | E4: Value | F4: Value/State Population | G4: Estimated In-City Victims, 2022, As if IC3 Victim Complaint | H4: State Victim Loss | I4: Even Loss per State Victim Count | J4: Projected In-City Victim Loss | K4: State Subject (Perpetrator) Count | L4: Subject (Perpetrator) to State Population | M4: Estimated Subject to City Population | N4: State Subject Losses (Perpetrator gained X dollars) | O4: Even Loss per State Subject | P4: Estimated In-City Subject Losses (Perpetrator Take from Victim)
B5: https://www.census.gov/quickfacts/fact/table/TN/PST045222 | C5: TN Population in 2018 | D5: Population Estimate | E5: 6771631 | F5: Raw Value | G5: (Victim Count/State Population ) * City Population | J5: Estimated In-City Victims * Even Loss per State Victim | P5: Subject to City * Even Loss per State Subject
B6: https://www.census.gov/quickfacts/chattanoogacitytennessee | C6: Chattanooga Population in 2018 | D6: Population Estimate | E6: 181918
B7: https://www.ic3.gov/Media/PDF/AnnualReport/2018State/StateReport.aspx#?s=47 | C7: Advanced Fee | D7: State Victim Count | E7: 275 | F7: =E7/E5 -> 4.06106e-05 | G7: =ROUNDDOWN(F7*E6,0) -> 7 | H7: 713685 | I7: =H7/E7 -> 2595.2182 | J7: =I7*G7 -> 18166.527 | K7: 66 | L7: =K7/E5 -> 9.7465441e-06 | M7: =ROUNDDOWN(L7*E6,0) -> 1 | N7: 516623 | O7: =N7/K7 -> 7827.6212 | P7: =M7*O7 -> 7827.6212
B8: https://www.ic3.gov/Media/PDF/AnnualReport/2018State/StateReport.aspx#?s=47 | C8: Business Email Compromise | D8: State Victim Count | E8: 297 | F8: =E8/E5 -> 4.3859448e-05 | G8: =ROUNDDOWN(F8*E6,0) -> 7 | H8: 16072195 | I8: =H8/E8 -> 54115.135 | J8: =I8*G8 -> 378805.94 | K8: 59 | L8: =K8/E5 -> 8.7128197e-06 | M8: =ROUNDDOWN(L8*E6,0) -> 1 | N8: 3628283 | O8: =N8/K8 -> 61496.322 | P8: =M8*O8 -> 61496.322
B9: https://www.ic3.gov/Media/PDF/AnnualReport/2018State/StateReport.aspx#?s=47 | C9: Botnet | D9: State Victim Count | F9: =E9/E5 -> 0 | G9: =ROUNDDOWN(F9*E6,0) -> 0 | I9: =H9/E9 -> #DIV/0! | J9: =I9*G9 -> #DIV/0! | L9: =K9/E5 -> 0 | M9: =ROUNDDOWN(L9*E6,0) -> 0 | O9: =N9/K9 -> #DIV/0! | P9: =M9*O9 -> #DIV/0!
B10: https://www.ic3.gov/Media/PDF/AnnualReport/2018State/StateReport.aspx#?s=47 | C10: Confidence/Romance | D10: State Victim Count | E10: 268 | F10: =E10/E5 -> 3.9576876e-05 | G10: =ROUNDDOWN(F10*E6,0) -> 7 | H10: 5101478 | I10: =H10/E10 -> 19035.366 | J10: =I10*G10 -> 133247.56 | K10: 112 | L10: =K10/E5 -> 1.653959e-05 | M10: =ROUNDDOWN(L10*E6,0) -> 3 | N10: 2307165 | O10: =N10/K10 -> 20599.688 | P10: =M10*O10 -> 61799.062
B11: https://www.ic3.gov/Media/PDF/AnnualReport/2018State/StateReport.aspx#?s=47 | C11: Check Fraud | D11: State Victim Count | F11: =E11/E5 -> 0 | G11: =ROUNDDOWN(F11*E6,0) -> 0 | I11: =H11/E11 -> #DIV/0! | J11: =I11*G11 -> #DIV/0! | L11: =K11/E5 -> 0 | M11: =ROUNDDOWN(L11*E6,0) -> 0 | O11: =N11/K11 -> #DIV/0! | P11: =M11*O11 -> #DIV/0!
B12: https://www.ic3.gov/Media/PDF/AnnualReport/2018State/StateReport.aspx#?s=47 | C12: Crimes Against Children | D12: State Victim Count | E12: 28 | F12: =E12/E5 -> 4.1348975e-06 | G12: =ROUNDDOWN(F12*E6,0) -> 0 | H12: 0 | I12: =H12/E12 -> 0 | J12: =I12*G12 -> 0 | K12: 8 | L12: =K12/E5 -> 1.1813993e-06 | M12: =ROUNDDOWN(L12*E6,0) -> 0 | N12: 0 | O12: =N12/K12 -> 0 | P12: =M12*O12 -> 0
B13: https://www.ic3.gov/Media/PDF/AnnualReport/2018State/StateReport.aspx#?s=47 | C13: Data Breach | D13: State Victim Count | E13: 28 | F13: =E13/E5 -> 4.1348975e-06 | G13: =ROUNDDOWN(F13*E6,0) -> 0 | H13: 476146 | I13: =H13/E13 -> 17005.214 | J13: =I13*G13 -> 0 | K13: 5 | L13: =K13/E5 -> 7.3837455e-07 | M13: =ROUNDDOWN(L13*E6,0) -> 0 | N13: 126300 | O13: =N13/K13 -> 25260 | P13: =M13*O13 -> 0
B14: https://www.ic3.gov/Media/PDF/AnnualReport/2018State/StateReport.aspx#?s=47 | C14: Employment | D14: State Victim Count | E14: 258 | F14: =E14/E5 -> 3.8100127e-05 | G14: =ROUNDDOWN(F14*E6,0) -> 6 | H14: 268247 | I14: =H14/E14 -> 1039.7171 | J14: =I14*G14 -> 6238.3023 | K14: 85 | L14: =K14/E5 -> 1.2552367e-05 | M14: =ROUNDDOWN(L14*E6,0) -> 2 | N14: 157215 | P14: =M14*O14 -> 0
B15: https://www.ic3.gov/Media/PDF/AnnualReport/2018State/StateReport.aspx#?s=47 | C15: Extortion | D15: State Victim Count | E15: 759 | F15: =E15/E5 -> 0.00011208526 | G15: =ROUNDDOWN(F15*E6,0) -> 20 | H15: 298202 | I15: =H15/E15 -> 392.88801 | J15: =I15*G15 -> 7857.7602 | K15: 105 | L15: =K15/E5 -> 1.5505866e-05 | M15: =ROUNDDOWN(L15*E6,0) -> 2 | N15: 258828 | P15: =M15*O15 -> 0
B16: https://www.ic3.gov/Media/PDF/AnnualReport/2018State/StateReport.aspx#?s=47 | C16: Government Impersonation | D16: State Victim Count | E16: 236 | F16: =E16/E5 -> 3.4851279e-05 | G16: =ROUNDDOWN(F16*E6,0) -> 6 | H16: 504683 | J16: =I16*G16 -> 0 | K16: 24 | L16: =K16/E5 -> 3.5441978e-06 | M16: =ROUNDDOWN(L16*E6,0) -> 0 | N16: 109665 | O16: =N16/K16 -> 4569.375 | P16: =M16*O16 -> 0
B17: https://www.ic3.gov/Media/PDF/AnnualReport/2018State/StateReport.aspx#?s=47 | C17: Harassing/Stalking | D17: State Victim Count | F17: =E17/E5 -> 0 | G17: =ROUNDDOWN(F17*E6,0) -> 0 | I17: =H17/E17 -> #DIV/0! | J17: =I17*G17 -> #DIV/0! | L17: =K17/E5 -> 0 | M17: =ROUNDDOWN(L17*E6,0) -> 0 | O17: =N17/K17 -> #DIV/0! | P17: =M17*O17 -> #DIV/0!
B18: https://www.ic3.gov/Media/PDF/AnnualReport/2018State/StateReport.aspx#?s=47 | C18: IPR/Counterfeit | D18: State Victim Count | E18: 25 | F18: =E18/E5 -> 3.6918728e-06 | G18: =ROUNDDOWN(F18*E6,0) -> 0 | H18: 62769 | I18: =H18/E18 -> 2510.76 | J18: =I18*G18 -> 0 | K18: 10 | L18: =K18/E5 -> 1.4767491e-06 | M18: =ROUNDDOWN(L18*E6,0) -> 0 | N18: 62431 | P18: =M18*O18 -> 0
B19: https://www.ic3.gov/Media/PDF/AnnualReport/2018State/StateReport.aspx#?s=47 | C19: Identity Theft | D19: State Victim Count | E19: 407 | F19: =E19/E5 -> 6.0103688e-05 | G19: =ROUNDDOWN(F19*E6,0) -> 10 | H19: 1271461 | I19: =H19/E19 -> 3123.9828 | J19: =I19*G19 -> 31239.828 | K19: 235 | L19: =K19/E5 -> 3.4703604e-05 | M19: =ROUNDDOWN(L19*E6,0) -> 6 | N19: 235577 | O19: =N19/K19 -> 1002.4553 | P19: =M19*O19 -> 6014.7319
B20: https://www.ic3.gov/Media/PDF/AnnualReport/2018State/StateReport.aspx#?s=47 | C20: Investment | D20: State Victim Count | E20: 17 | F20: =E20/E5 -> 2.5104735e-06 | G20: =ROUNDDOWN(F20*E6,0) -> 0 | H20: 1124651 | I20: =H20/E20 -> 66155.941 | J20: =I20*G20 -> 0 | K20: 9 | L20: =K20/E5 -> 1.3290742e-06 | M20: =ROUNDDOWN(L20*E6,0) -> 0 | N20: 1959171 | O20: =N20/K20 -> 217685.67 | P20: =M20*O20 -> 0
B21: https://www.ic3.gov/Media/PDF/AnnualReport/2018State/StateReport.aspx#?s=47 | C21: Lottery/Sweepstakes/Inheritance | D21: State Victim Count | E21: 117 | F21: =E21/E5 -> 1.7277964e-05 | G21: =ROUNDDOWN(F21*E6,0) -> 3 | H21: 35007 | I21: =H21/E21 -> 299.20513 | J21: =I21*G21 -> 897.61538 | K21: 20 | L21: =K21/E5 -> 2.9534982e-06 | M21: =ROUNDDOWN(L21*E6,0) -> 0 | N21: 185881 | O21: =N21/K21 -> 9294.05 | P21: =M21*O21 -> 0
B22: https://www.ic3.gov/Media/PDF/AnnualReport/2018State/StateReport.aspx#?s=47 | C22: Malware | D22: State Victim Count | E22: 23 | F22: =E22/E5 -> 3.3965229e-06 | G22: =ROUNDDOWN(F22*E6,0) -> 0 | H22: 150 | I22: =H22/E22 -> 6.5217391 | J22: =I22*G22 -> 0 | K22: 5 | L22: =K22/E5 -> 7.3837455e-07 | M22: =ROUNDDOWN(L22*E6,0) -> 0 | N22: 1758 | O22: =N22/K22 -> 351.6 | P22: =M22*O22 -> 0
B23: https://www.ic3.gov/Media/PDF/AnnualReport/2018State/StateReport.aspx#?s=47 | C23: NCDF | D23: State Victim Count | F23: =E23/E5 -> 0 | G23: =ROUNDDOWN(F23*E6,0) -> 0 | I23: =H23/E23 -> #DIV/0! | J23: =I23*G23 -> #DIV/0! | L23: =K23/E5 -> 0 | M23: =ROUNDDOWN(L23*E6,0) -> 0 | O23: =N23/K23 -> #DIV/0! | P23: =M23*O23 -> #DIV/0!
B24: https://www.ic3.gov/Media/PDF/AnnualReport/2018State/StateReport.aspx#?s=47 | C24: NTOC | D24: State Victim Count | F24: =E24/E5 -> 0 | G24: =ROUNDDOWN(F24*E6,0) -> 0 | I24: =H24/E24 -> #DIV/0! | J24: =I24*G24 -> #DIV/0! | L24: =K24/E5 -> 0 | M24: =ROUNDDOWN(L24*E6,0) -> 0 | O24: =N24/K24 -> #DIV/0! | P24: =M24*O24 -> #DIV/0!
B25: https://www.ic3.gov/Media/PDF/AnnualReport/2018State/StateReport.aspx#?s=47 | C25: No Lead Value | D25: State Victim Count | E25: 691 | F25: =E25/E5 -> 0.00010204336 | G25: =ROUNDDOWN(F25*E6,0) -> 18 | H25: 2000 | I25: =H25/E25 -> 2.894356 | J25: =I25*G25 -> 52.098408 | K25: 501 | L25: =K25/E5 -> 7.398513e-05 | M25: =ROUNDDOWN(L25*E6,0) -> 13 | N25: 0 | O25: =N25/K25 -> 0 | P25: =M25*O25 -> 0
B26: https://www.ic3.gov/Media/PDF/AnnualReport/2018State/StateReport.aspx#?s=47 | C26: Non-Payable/Non-Delivery | D26: State Victim Count | E26: 1020 | F26: =E26/E5 -> 0.00015062841 | G26: =ROUNDDOWN(F26*E6,0) -> 27 | H26: 2450142 | I26: =H26/E26 -> 2402.1 | J26: =I26*G26 -> 64856.7 | K26: 350 | L26: =K26/E5 -> 5.1686219e-05 | M26: =ROUNDDOWN(L26*E6,0) -> 9 | N26: 1352168 | O26: =N26/K26 -> 3863.3371 | P26: =M26*O26 -> 34770.034
B27: https://www.ic3.gov/Media/PDF/AnnualReport/2018State/StateReport.aspx#?s=47 | C27: Other | D27: State Victim Count | E27: 146 | F27: =E27/E5 -> 2.1560537e-05 | G27: =ROUNDDOWN(F27*E6,0) -> 3 | H27: 98342 | I27: =H27/E27 -> 673.57534 | J27: =I27*G27 -> 2020.726 | K27: 64 | L27: =K27/E5 -> 9.4511943e-06 | M27: =ROUNDDOWN(L27*E6,0) -> 1 | N27: 212276 | O27: =N27/K27 -> 3316.8125 | P27: =M27*O27 -> 3316.8125
B28: https://www.ic3.gov/Media/PDF/AnnualReport/2018State/StateReport.aspx#?s=47 | C28: Overpayment | D28: State Victim Count | E28: 228 | F28: =E28/E5 -> 3.366988e-05 | G28: =ROUNDDOWN(F28*E6,0) -> 6 | H28: 205197 | I28: =H28/E28 -> 899.98684 | J28: =I28*G28 -> 5399.9211 | K28: 91 | L28: =K28/E5 -> 1.3438417e-05 | M28: =ROUNDDOWN(L28*E6,0) -> 2 | N28: 164202 | O28: =N28/K28 -> 1804.4176 | P28: =M28*O28 -> 3608.8352
B29: https://www.ic3.gov/Media/PDF/AnnualReport/2018State/StateReport.aspx#?s=47 | C29: Personal Data Breach | D29: State Victim Count | E29: 697 | F29: =E29/E5 -> 0.00010292941 | G29: =ROUNDDOWN(F29*E6,0) -> 18 | H29: 1078377 | I29: =H29/E29 -> 1547.1693 | J29: =I29*G29 -> 27849.047 | K29: 187 | L29: =K29/E5 -> 2.7615208e-05 | M29: =ROUNDDOWN(L29*E6,0) -> 5 | N29: 534473 | O29: =N29/K29 -> 2858.1444 | P29: =M29*O29 -> 14290.722
B30: https://www.ic3.gov/Media/PDF/AnnualReport/2018State/StateReport.aspx#?s=47 | C30: Phishing | D30: State Victim Count | E30: 311 | F30: =E30/E5 -> 4.5926897e-05 | G30: =ROUNDDOWN(F30*E6,0) -> 8 | H30: 236437 | I30: =H30/E30 -> 760.24759 | J30: =I30*G30 -> 6081.9807 | K30: 52 | L30: =K30/E5 -> 7.6790953e-06 | M30: =ROUNDDOWN(L30*E6,0) -> 1 | N30: 256030 | O30: =N30/K30 -> 4923.6538 | P30: =M30*O30 -> 4923.6538
B31: https://www.ic3.gov/Media/PDF/AnnualReport/2018State/StateReport.aspx#?s=47 | C31: Ransomware | D31: State Victim Count | E31: 20 | F31: =E31/E5 -> 2.9534982e-06 | G31: =ROUNDDOWN(F31*E6,0) -> 0 | H31: 36722 | I31: =H31/E31 -> 1836.1 | J31: =I31*G31 -> 0 | K31: 1 | L31: =K31/E5 -> 1.4767491e-07 | M31: =ROUNDDOWN(L31*E6,0) -> 0 | N31: 0 | O31: =N31/K31 -> 0 | P31: =M31*O31 -> 0
B32: https://www.ic3.gov/Media/PDF/AnnualReport/2018State/StateReport.aspx#?s=47 | C32: Real Estate | D32: State Victim Count | E32: 154 | F32: =E32/E5 -> 2.2741936e-05 | G32: =ROUNDDOWN(F32*E6,0) -> 4 | H32: 1252773 | I32: =H32/E32 -> 8134.8896 | J32: =I32*G32 -> 32539.558 | K32: 94 | L32: =K32/E5 -> 1.3881442e-05 | M32: =ROUNDDOWN(L32*E6,0) -> 2 | N32: 730382 | O32: =N32/K32 -> 7770.0213 | P32: =M32*O32 -> 15540.043
B33: https://www.ic3.gov/Media/PDF/AnnualReport/2018State/StateReport.aspx#?s=47 | C33: SIM Swap | D33: State Victim Count | F33: =E33/E5 -> 0 | G33: =ROUNDDOWN(F33*E6,0) -> 0 | I33: =H33/E33 -> #DIV/0! | J33: =I33*G33 -> #DIV/0! | L33: =K33/E5 -> 0 | M33: =ROUNDDOWN(L33*E6,0) -> 0 | O33: =N33/K33 -> #DIV/0! | P33: =M33*O33 -> #DIV/0!
B34: https://www.ic3.gov/Media/PDF/AnnualReport/2018State/StateReport.aspx#?s=47 | C34: Spoofing | D34: State Victim Count | E34: 193 | F34: =E34/E5 -> 2.8501258e-05 | G34: =ROUNDDOWN(F34*E6,0) -> 5 | H34: 297281 | I34: =H34/E34 -> 1540.3161 | J34: =I34*G34 -> 7701.5803 | K34: 40 | L34: =K34/E5 -> 5.9069964e-06 | M34: =ROUNDDOWN(L34*E6,0) -> 1 | N34: 429686 | O34: =N34/K34 -> 10742.15 | P34: =M34*O34 -> 10742.15
B35: https://www.ic3.gov/Media/PDF/AnnualReport/2018State/StateReport.aspx#?s=47 | C35: Tech Support | D35: State Victim Count | E35: 245 | F35: =E35/E5 -> 3.6180353e-05 | G35: =ROUNDDOWN(F35*E6,0) -> 6 | H35: 405006 | I35: =H35/E35 -> 1653.0857 | J35: =I35*G35 -> 9918.5143 | K35: 28 | L35: =K35/E5 -> 4.1348975e-06 | M35: =ROUNDDOWN(L35*E6,0) -> 0 | N35: 214280 | O35: =N35/K35 -> 7652.8571 | P35: =M35*O35 -> 0
B36: https://www.ic3.gov/Media/PDF/AnnualReport/2018State/StateReport.aspx#?s=47 | C36: Threats of Violence | D36: State Victim Count | E36: 262 | F36: =E36/E5 -> 3.8690826e-05 | G36: =ROUNDDOWN(F36*E6,0) -> 7 | H36: 110608 | I36: =H36/E36 -> 422.16794 | J36: =I36*G36 -> 2955.1756 | K36: 125 | L36: =K36/E5 -> 1.8459364e-05 | M36: =ROUNDDOWN(L36*E6,0) -> 3 | N36: 91667 | O36: =N36/K36 -> 733.336 | P36: =M36*O36 -> 2200.008
J37: =I37*G37 -> 0
E38: =SUM(E7:E36) -> 6705 | G38: =SUM(G8:G36) -> 161 | I38: =H38/E38 -> 0 | J38: =I38*G38 -> 0
C39: Harassment/Stalking/Threats of Violence/Terrorism combined

Sheet 2019_IC3 State to City
B4: REF URL | C4: Decription | D4: Unit | E4: Value | F4: Value/State Population | G4: Estimated In-City Victims, 2022, As if IC3 Victim Complaint | H4: State Victim Loss | I4: Even Loss per State Victim Count | J4: Projected In-City Victim Loss | K4: State Subject (Perpetrator) Count | L4: Subject (Perpetrator) to State Population | M4: Estimated Subject to City Population | N4: State Subject Losses (Perpetrator gained X dollars) | O4: Even Loss per State Subject | P4: Estimated In-City Subject Losses (Perpetrator Take from Victim)
B5: https://www2.census.gov/programs-surveys/popest/tables/2010-2019/state/totals/nst-est2019-01.xlsx | C5: TN Population in 2019 | D5: Population Estimate | E5: 6829174 | F5: Raw Value | G5: (Victim Count/State Population ) * City Population | J5: Estimated In-City Victims * Even Loss per State Victim | P5: Subject to City * Even Loss per State Subject
B6: https://www2.census.gov/programs-surveys/popest/tables/2010-2019/cities/totals/SUB-IP-EST2019-ANNRES-47.xlsx | C6: Chattanooga Population in 2019 | D6: Population Estimate | E6: 182799
B7: https://www.ic3.gov/Media/PDF/AnnualReport/2019State/StateReport.aspx#?s=47 | C7: Advanced Fee | D7: State Victim Count | E7: 213 | F7: =E7/E5 -> 3.1189716e-05 | G7: =ROUNDDOWN(F7*E6,0) -> 5 | H7: 1071731 | I7: =H7/E7 -> 5031.6009 | J7: =I7*G7 -> 25158.005 | K7: 50 | L7: =K7/E5 -> 7.3215297e-06 | M7: =ROUNDDOWN(L7*E6,0) -> 1 | N7: 607608 | O7: =N7/K7 -> 12152.16 | P7: =M7*O7 -> 12152.16
B8: https://www.ic3.gov/Media/PDF/AnnualReport/2019State/StateReport.aspx#?s=47 | C8: Business Email Compromise | D8: State Victim Count | E8: 331 | F8: =E8/E5 -> 4.8468526e-05 | G8: =ROUNDDOWN(F8*E6,0) -> 8 | H8: 12938403 | I8: =H8/E8 -> 39088.831 | J8: =I8*G8 -> 312710.65 | K8: 60 | L8: =K8/E5 -> 8.7858356e-06 | M8: =ROUNDDOWN(L8*E6,0) -> 1 | N8: 7348472 | O8: =N8/K8 -> 122474.53 | P8: =M8*O8 -> 122474.53
B9: https://www.ic3.gov/Media/PDF/AnnualReport/2019State/StateReport.aspx#?s=47 | C9: Botnet | D9: State Victim Count | F9: =E9/E5 -> 0 | G9: =ROUNDDOWN(F9*E6,0) -> 0 | I9: =H9/E9 -> #DIV/0! | J9: =I9*G9 -> #DIV/0! | L9: =K9/E5 -> 0 | M9: =ROUNDDOWN(L9*E6,0) -> 0 | O9: =N9/K9 -> #DIV/0! | P9: =M9*O9 -> #DIV/0!
B10: https://www.ic3.gov/Media/PDF/AnnualReport/2019State/StateReport.aspx#?s=47 | C10: Confidence/Romance | D10: State Victim Count | E10: 293 | F10: =E10/E5 -> 4.2904164e-05 | G10: =ROUNDDOWN(F10*E6,0) -> 7 | H10: 4948521 | I10: =H10/E10 -> 16889.15 | J10: =I10*G10 -> 118224.05 | K10: 131 | L10: =K10/E5 -> 1.9182408e-05 | M10: =ROUNDDOWN(L10*E6,0) -> 3 | N10: 2571226 | O10: =N10/K10 -> 19627.679 | P10: =M10*O10 -> 58883.038
B11: https://www.ic3.gov/Media/PDF/AnnualReport/2019State/StateReport.aspx#?s=47 | C11: Check Fraud | D11: State Victim Count | F11: =E11/E5 -> 0 | G11: =ROUNDDOWN(F11*E6,0) -> 0 | I11: =H11/E11 -> #DIV/0! | J11: =I11*G11 -> #DIV/0! | L11: =K11/E5 -> 0 | M11: =ROUNDDOWN(L11*E6,0) -> 0 | O11: =N11/K11 -> #DIV/0! | P11: =M11*O11 -> #DIV/0!
B12: https://www.ic3.gov/Media/PDF/AnnualReport/2019State/StateReport.aspx#?s=47 | C12: Crimes Against Children | D12: State Victim Count | E12: 23 | F12: =E12/E5 -> 3.3679036e-06 | G12: =ROUNDDOWN(F12*E6,0) -> 0 | H12: 0 | I12: =H12/E12 -> 0 | J12: =I12*G12 -> 0 | K12: 5 | L12: =K12/E5 -> 7.3215297e-07 | M12: =ROUNDDOWN(L12*E6,0) -> 0 | N12: 0 | O12: =N12/K12 -> 0 | P12: =M12*O12 -> 0
B13: https://www.ic3.gov/Media/PDF/AnnualReport/2019State/StateReport.aspx#?s=47 | C13: Data Breach | D13: State Victim Count | E13: 21 | F13: =E13/E5 -> 3.0750425e-06 | G13: =ROUNDDOWN(F13*E6,0) -> 0 | H13: 2572 | I13: =H13/E13 -> 122.47619 | J13: =I13*G13 -> 0 | K13: 1 | L13: =K13/E5 -> 1.4643059e-07 | M13: =ROUNDDOWN(L13*E6,0) -> 0 | N13: 0 | O13: =N13/K13 -> 0 | P13: =M13*O13 -> 0
B14: https://www.ic3.gov/Media/PDF/AnnualReport/2019State/StateReport.aspx#?s=47 | C14: Employment | D14: State Victim Count | E14: 208 | F14: =E14/E5 -> 3.0457563e-05 | G14: =ROUNDDOWN(F14*E6,0) -> 5 | H14: 394010 | I14: =H14/E14 -> 1894.2788 | J14: =I14*G14 -> 9471.3942 | K14: 64 | L14: =K14/E5 -> 9.371558e-06 | M14: =ROUNDDOWN(L14*E6,0) -> 1 | N14: 208089 | O14: =N14/K14 -> 3251.3906 | P14: =M14*O14 -> 3251.3906
B15: https://www.ic3.gov/Media/PDF/AnnualReport/2019State/StateReport.aspx#?s=47 | C15: Extortion | D15: State Victim Count | E15: 725 | F15: =E15/E5 -> 0.00010616218 | G15: =ROUNDDOWN(F15*E6,0) -> 19 | H15: 629565 | J15: =I15*G15 -> 0 | K15: 93 | L15: =K15/E5 -> 1.3618045e-05 | M15: =ROUNDDOWN(L15*E6,0) -> 2 | N15: 87152 | O15: =N15/K15 -> 937.11828 | P15: =M15*O15 -> 1874.2366
B16: https://www.ic3.gov/Media/PDF/AnnualReport/2019State/StateReport.aspx#?s=47 | C16: Government Impersonation | D16: State Victim Count | E16: 227 | F16: =E16/E5 -> 3.3239745e-05 | G16: =ROUNDDOWN(F16*E6,0) -> 6 | H16: 555364 | I16: =H16/E16 -> 2446.5374 | J16: =I16*G16 -> 14679.225 | K16: 29 | L16: =K16/E5 -> 4.2464872e-06 | M16: =ROUNDDOWN(L16*E6,0) -> 0 | N16: 83100 | O16: =N16/K16 -> 2865.5172 | P16: =M16*O16 -> 0
B17: https://www.ic3.gov/Media/PDF/AnnualReport/2019State/StateReport.aspx#?s=47 | C17: Harassing/Stalking | D17: State Victim Count | F17: =E17/E5 -> 0 | G17: =ROUNDDOWN(F17*E6,0) -> 0 | I17: =H17/E17 -> #DIV/0! | J17: =I17*G17 -> #DIV/0! | L17: =K17/E5 -> 0 | M17: =ROUNDDOWN(L17*E6,0) -> 0 | O17: =N17/K17 -> #DIV/0! | P17: =M17*O17 -> #DIV/0!
B18: https://www.ic3.gov/Media/PDF/AnnualReport/2019State/StateReport.aspx#?s=47 | C18: IPR/Counterfeit | D18: State Victim Count | E18: 58 | F18: =E18/E5 -> 8.4929744e-06 | G18: =ROUNDDOWN(F18*E6,0) -> 1 | H18: 195407 | I18: =H18/E18 -> 3369.0862 | J18: =I18*G18 -> 3369.0862 | K18: 8 | L18: =K18/E5 -> 1.1714447e-06 | M18: =ROUNDDOWN(L18*E6,0) -> 0 | N18: 2925 | O18: =N18/K18 -> 365.625 | P18: =M18*O18 -> 0
B19: https://www.ic3.gov/Media/PDF/AnnualReport/2019State/StateReport.aspx#?s=47 | C19: Identity Theft | D19: State Victim Count | E19: 289 | F19: =E19/E5 -> 4.2318441e-05 | G19: =ROUNDDOWN(F19*E6,0) -> 7 | H19: 896835 | I19: =H19/E19 -> 3103.2353 | J19: =I19*G19 -> 21722.647 | K19: 91 | L19: =K19/E5 -> 1.3325184e-05 | M19: =ROUNDDOWN(L19*E6,0) -> 2 | N19: 392223 | O19: =N19/K19 -> 4310.1429 | P19: =M19*O19 -> 8620.2857
B20: https://www.ic3.gov/Media/PDF/AnnualReport/2019State/StateReport.aspx#?s=47 | C20: Investment | D20: State Victim Count | E20: 35 | F20: =E20/E5 -> 5.1250708e-06 | G20: =ROUNDDOWN(F20*E6,0) -> 0 | H20: 7667267 | I20: =H20/E20 -> 219064.77 | J20: =I20*G20 -> 0 | K20: 25 | L20: =K20/E5 -> 3.6607648e-06 | M20: =ROUNDDOWN(L20*E6,0) -> 0 | N20: 515037 | O20: =N20/K20 -> 20601.48 | P20: =M20*O20 -> 0
B21: https://www.ic3.gov/Media/PDF/AnnualReport/2019State/StateReport.aspx#?s=47 | C21: Lottery/Sweepstakes/Inheritance | D21: State Victim Count | E21: 113 | F21: =E21/E5 -> 1.6546657e-05 | G21: =ROUNDDOWN(F21*E6,0) -> 3 | H21: 595993 | I21: =H21/E21 -> 5274.2743 | J21: =I21*G21 -> 15822.823 | K21: 18 | L21: =K21/E5 -> 2.6357507e-06 | M21: =ROUNDDOWN(L21*E6,0) -> 0 | N21: 1168782 | O21: =N21/K21 -> 64932.333 | P21: =M21*O21 -> 0
B22: https://www.ic3.gov/Media/PDF/AnnualReport/2019State/StateReport.aspx#?s=47 | C22: Malware | D22: State Victim Count | E22: 46 | F22: =E22/E5 -> 6.7358073e-06 | G22: =ROUNDDOWN(F22*E6,0) -> 1 | H22: 707 | I22: =H22/E22 -> 15.369565 | J22: =I22*G22 -> 15.369565 | K22: 5 | L22: =K22/E5 -> 7.3215297e-07 | M22: =ROUNDDOWN(L22*E6,0) -> 0 | N22: 0 | O22: =N22/K22 -> 0 | P22: =M22*O22 -> 0
B23: https://www.ic3.gov/Media/PDF/AnnualReport/2019State/StateReport.aspx#?s=47 | C23: NCDF | D23: State Victim Count | F23: =E23/E5 -> 0 | G23: =ROUNDDOWN(F23*E6,0) -> 0 | I23: =H23/E23 -> #DIV/0! | J23: =I23*G23 -> #DIV/0! | L23: =K23/E5 -> 0 | M23: =ROUNDDOWN(L23*E6,0) -> 0 | O23: =N23/K23 -> #DIV/0! | P23: =M23*O23 -> #DIV/0!
B24: https://www.ic3.gov/Media/PDF/AnnualReport/2019State/StateReport.aspx#?s=47 | C24: NTOC | D24: State Victim Count | F24: =E24/E5 -> 0 | G24: =ROUNDDOWN(F24*E6,0) -> 0 | I24: =H24/E24 -> #DIV/0! | J24: =I24*G24 -> #DIV/0! | L24: =K24/E5 -> 0 | M24: =ROUNDDOWN(L24*E6,0) -> 0 | O24: =N24/K24 -> #DIV/0! | P24: =M24*O24 -> #DIV/0!
B25: https://www.ic3.gov/Media/PDF/AnnualReport/2019State/StateReport.aspx#?s=47 | C25: No Lead Value | D25: State Victim Count | E25: 629 | F25: =E25/E5 -> 9.2104843e-05 | G25: =ROUNDDOWN(F25*E6,0) -> 16 | H25: 0 | I25: =H25/E25 -> 0 | J25: =I25*G25 -> 0 | K25: 746 | L25: =K25/E5 -> 0.00010923722 | M25: =ROUNDDOWN(L25*E6,0) -> 19 | N25: 0 | O25: =N25/K25 -> 0 | P25: =M25*O25 -> 0
B26: https://www.ic3.gov/Media/PDF/AnnualReport/2019State/StateReport.aspx#?s=47 | C26: Non-Payable/Non-Delivery | D26: State Victim Count | E26: 1067 | F26: =E26/E5 -> 0.00015624144 | G26: =ROUNDDOWN(F26*E6,0) -> 28 | H26: 1641120 | I26: =H26/E26 -> 1538.0694 | J26: =I26*G26 -> 43065.942 | K26: 404 | L26: =K26/E5 -> 5.915796e-05 | M26: =ROUNDDOWN(L26*E6,0) -> 10 | N26: 807007 | O26: =N26/K26 -> 1997.5421 | P26: =M26*O26 -> 19975.421
B27: https://www.ic3.gov/Media/PDF/AnnualReport/2019State/StateReport.aspx#?s=47 | C27: Other | D27: State Victim Count | E27: 83 | F27: =E27/E5 -> 1.2153739e-05 | G27: =ROUNDDOWN(F27*E6,0) -> 2 | H27: 629450 | I27: =H27/E27 -> 7583.7349 | J27: =I27*G27 -> 15167.47 | K27: 34 | L27: =K27/E5 -> 4.9786402e-06 | M27: =ROUNDDOWN(L27*E6,0) -> 0 | N27: 827641 | O27: =N27/K27 -> 24342.382 | P27: =M27*O27 -> 0
B28: https://www.ic3.gov/Media/PDF/AnnualReport/2019State/StateReport.aspx#?s=47 | C28: Overpayment | D28: State Victim Count | E28: 222 | F28: =E28/E5 -> 3.2507592e-05 | G28: =ROUNDDOWN(F28*E6,0) -> 5 | H28: 826044 | I28: =H28/E28 -> 3720.9189 | J28: =I28*G28 -> 18604.595 | K28: 97 | L28: =K28/E5 -> 1.4203768e-05 | M28: =ROUNDDOWN(L28*E6,0) -> 2 | N28: 428273 | O28: =N28/K28 -> 4415.1856 | P28: =M28*O28 -> 8830.3711
B29: https://www.ic3.gov/Media/PDF/AnnualReport/2019State/StateReport.aspx#?s=47 | C29: Personal Data Breach | D29: State Victim Count | E29: 507 | F29: =E29/E5 -> 7.4240311e-05 | G29: =ROUNDDOWN(F29*E6,0) -> 13 | H29: 750727 | I29: =H29/E29 -> 1480.7239 | J29: =I29*G29 -> 19249.41 | K29: 147 | L29: =K29/E5 -> 2.1525297e-05 | M29: =ROUNDDOWN(L29*E6,0) -> 3 | N29: 278229 | O29: =N29/K29 -> 1892.7143 | P29: =M29*O29 -> 5678.1429
B30: https://www.ic3.gov/Media/PDF/AnnualReport/2019State/StateReport.aspx#?s=47 | C30: Phishing | D30: State Victim Count | E30: 310 | F30: =E30/E5 -> 4.5393484e-05 | G30: =ROUNDDOWN(F30*E6,0) -> 8 | H30: 127466 | I30: =H30/E30 -> 411.18065 | J30: =I30*G30 -> 3289.4452 | K30: 51 | L30: =K30/E5 -> 7.4679603e-06 | M30: =ROUNDDOWN(L30*E6,0) -> 1 | N30: 57192 | O30: =N30/K30 -> 1121.4118 | P30: =M30*O30 -> 1121.4118
B31: https://www.ic3.gov/Media/PDF/AnnualReport/2019State/StateReport.aspx#?s=47 | C31: Ransomware | D31: State Victim Count | E31: 34 | F31: =E31/E5 -> 4.9786402e-06 | G31: =ROUNDDOWN(F31*E6,0) -> 0 | H31: 16325 | I31: =H31/E31 -> 480.14706 | J31: =I31*G31 -> 0 | K31: 4 | L31: =K31/E5 -> 5.8572237e-07 | M31: =ROUNDDOWN(L31*E6,0) -> 0 | N31: 200 | O31: =N31/K31 -> 50 | P31: =M31*O31 -> 0
B32: https://www.ic3.gov/Media/PDF/AnnualReport/2019State/StateReport.aspx#?s=47 | C32: Real Estate | D32: State Victim Count | E32: 144 | F32: =E32/E5 -> 2.1086005e-05 | G32: =ROUNDDOWN(F32*E6,0) -> 3 | H32: 1090182 | I32: =H32/E32 -> 7570.7083 | J32: =I32*G32 -> 22712.125 | K32: 76 | L32: =K32/E5 -> 1.1128725e-05 | M32: =ROUNDDOWN(L32*E6,0) -> 2 | N32: 4483062 | O32: =N32/K32 -> 58987.658 | P32: =M32*O32 -> 117975.32
B33: https://www.ic3.gov/Media/PDF/AnnualReport/2019State/StateReport.aspx#?s=47 | C33: SIM Swap | D33: State Victim Count | F33: =E33/E5 -> 0 | G33: =ROUNDDOWN(F33*E6,0) -> 0 | I33: =H33/E33 -> #DIV/0! | J33: =I33*G33 -> #DIV/0! | L33: =K33/E5 -> 0 | M33: =ROUNDDOWN(L33*E6,0) -> 0 | O33: =N33/K33 -> #DIV/0! | P33: =M33*O33 -> #DIV/0!
B34: https://www.ic3.gov/Media/PDF/AnnualReport/2019State/StateReport.aspx#?s=47 | C34: Spoofing | D34: State Victim Count | E34: 343 | F34: =E34/E5 -> 5.0225693e-05 | G34: =ROUNDDOWN(F34*E6,0) -> 9 | H34: 3477664 | I34: =H34/E34 -> 10138.962 | J34: =I34*G34 -> 91250.659 | K34: 72 | L34: =K34/E5 -> 1.0543003e-05 | M34: =ROUNDDOWN(L34*E6,0) -> 1 | N34: 689474 | O34: =N34/K34 -> 9576.0278 | P34: =M34*O34 -> 9576.0278
B35: https://www.ic3.gov/Media/PDF/AnnualReport/2019State/StateReport.aspx#?s=47 | C35: Tech Support | D35: State Victim Count | E35: 232 | F35: =E35/E5 -> 3.3971898e-05 | G35: =ROUNDDOWN(F35*E6,0) -> 6 | H35: 729247 | I35: =H35/E35 -> 3143.306 | J35: =I35*G35 -> 18859.836 | K35: 29 | L35: =K35/E5 -> 4.2464872e-06 | M35: =ROUNDDOWN(L35*E6,0) -> 0 | N35: 49275 | O35: =N35/K35 -> 1699.1379 | P35: =M35*O35 -> 0
B36: https://www.ic3.gov/Media/PDF/AnnualReport/2019State/StateReport.aspx#?s=47 | C36: Threats of Violence | D36: State Victim Count | E36: 199 | F36: =E36/E5 -> 2.9139688e-05 | G36: =ROUNDDOWN(F36*E6,0) -> 5 | H36: 18762 | I36: =H36/E36 -> 94.281407 | J36: =I36*G36 -> 471.40704 | K36: 120 | L36: =K36/E5 -> 1.7571671e-05 | M36: =ROUNDDOWN(L36*E6,0) -> 3 | N36: 119327 | O36: =N36/K36 -> 994.39167 | P36: =M36*O36 -> 2983.175
J37: =I37*G37 -> 0
E38: =SUM(E7:E36) -> 6352 | G38: =SUM(G8:G36) -> 152 | I38: =H38/E38 -> 0 | J38: =I38*G38 -> 0
C40: Stalking/Harassment and Threats of violence were combined with Terrorism
C41: Shown here as Threats of Violence, as with others.

Sheet 2020_IC3 State to City
B4: REF URL | C4: Decription | D4: Unit | E4: Value | F4: Value/State Population | G4: Estimated In-City Victims, 2022, As if IC3 Victim Complaint | H4: State Victim Loss | I4: Even Loss per State Victim Count | J4: Projected In-City Victim Loss | K4: State Subject (Perpetrator) Count | L4: Subject (Perpetrator) to State Population | M4: Estimated Subject to City Population | N4: State Subject Losses (Perpetrator gained X dollars) | O4: Even Loss per State Subject | P4: Estimated In-City Subject Losses (Perpetrator Take from Victim)
B5: https://www2.census.gov/programs-surveys/popest/datasets/2020-2022/state/totals/NST-EST2022-POPCHG2020_2022.csv | C5: TN Population in 2020 | D5: Population Estimate | E5: 6925619 | F5: Raw Value | G5: (Victim Count/State Population ) * City Population | J5: Estimated In-City Victims * Even Loss per State Victim | P5: Subject to City * Even Loss per State Subject
B6: https://www.census.gov/data/tables/time-series/demo/popest/2020s-total-cities-and-towns.html | C6: Chattanooga Population in 2020 | D6: Population Estimate | E6: 181560
B7: https://www.ic3.gov/Media/PDF/AnnualReport/2020State/StateReport.aspx#?s=47 | C7: Advanced Fee | D7: State Victim Count | E7: 219 | F7: =E7/E5 -> 3.1621722e-05 | G7: =ROUNDDOWN(F7*E6,0) -> 5 | H7: 563344 | I7: =H7/E7 -> 2572.347 | J7: =I7*G7 -> 12861.735 | K7: 57 | L7: =K7/E5 -> 8.2303113e-06 | M7: =ROUNDDOWN(L7*E6,0) -> 1 | N7: 147490 | O7: =N7/K7 -> 2587.5439 | P7: =M7*O7 -> 2587.5439
B8: https://www.ic3.gov/Media/PDF/AnnualReport/2020State/StateReport.aspx#?s=47 | C8: Business Email Compromise | D8: State Victim Count | E8: 249 | F8: =E8/E5 -> 3.5953465e-05 | G8: =ROUNDDOWN(F8*E6,0) -> 6 | H8: 20831147 | I8: =H8/E8 -> 83659.225 | J8: =I8*G8 -> 501955.35 | K8: 41 | L8: =K8/E5 -> 5.9200484e-06 | M8: =ROUNDDOWN(L8*E6,0) -> 1 | N8: 3163786 | O8: =N8/K8 -> 77165.512 | P8: =M8*O8 -> 77165.512
B9: https://www.ic3.gov/Media/PDF/AnnualReport/2020State/StateReport.aspx#?s=47 | C9: Botnet | D9: State Victim Count | E9: NO MATCH | F9: =E9/E5 -> #VALUE! | G9: =ROUNDDOWN(F9*E6,0) -> #VALUE! | I9: =H9/E9 -> #VALUE! | J9: =I9*G9 -> #VALUE! | L9: =K9/E5 -> 0 | M9: =ROUNDDOWN(L9*E6,0) -> 0 | O9: =N9/K9 -> #DIV/0! | P9: =M9*O9 -> #DIV/0!
B10: https://www.ic3.gov/Media/PDF/AnnualReport/2020State/StateReport.aspx#?s=47 | C10: Confidence/Romance | D10: State Victim Count | E10: 334 | F10: =E10/E5 -> 4.8226736e-05 | G10: =ROUNDDOWN(F10*E6,0) -> 8 | H10: 4526218 | I10: =H10/E10 -> 13551.551 | J10: =I10*G10 -> 108412.41 | K10: 119 | L10: =K10/E5 -> 1.718258e-05 | M10: =ROUNDDOWN(L10*E6,0) -> 3 | N10: 2617420 | O10: =N10/K10 -> 21995.126 | P10: =M10*O10 -> 65985.378
B11: https://www.ic3.gov/Media/PDF/AnnualReport/2020State/StateReport.aspx#?s=47 | C11: Check Fraud | D11: State Victim Count | E11: NO MATCH | F11: =E11/E5 -> #VALUE! | G11: =ROUNDDOWN(F11*E6,0) -> #VALUE! | I11: =H11/E11 -> #VALUE! | J11: =I11*G11 -> #VALUE! | L11: =K11/E5 -> 0 | M11: =ROUNDDOWN(L11*E6,0) -> 0 | O11: =N11/K11 -> #DIV/0! | P11: =M11*O11 -> #DIV/0!
B12: https://www.ic3.gov/Media/PDF/AnnualReport/2020State/StateReport.aspx#?s=47 | C12: Crimes Against Children | D12: State Victim Count | E12: 60 | F12: =E12/E5 -> 8.6634855e-06 | G12: =ROUNDDOWN(F12*E6,0) -> 1 | H12: 0 | I12: =H12/E12 -> 0 | J12: =I12*G12 -> 0 | K12: 12 | L12: =K12/E5 -> 1.7326971e-06 | M12: =ROUNDDOWN(L12*E6,0) -> 0 | N12: 0 | O12: =N12/K12 -> 0 | P12: =M12*O12 -> 0
B13: https://www.ic3.gov/Media/PDF/AnnualReport/2020State/StateReport.aspx#?s=47 | C13: Data Breach | D13: State Victim Count | E13: 29 | F13: =E13/E5 -> 4.1873513e-06 | G13: =ROUNDDOWN(F13*E6,0) -> 0 | H13: 1227717 | I13: =H13/E13 -> 42335.069 | J13: =I13*G13 -> 0 | K13: 5 | L13: =K13/E5 -> 7.2195713e-07 | M13: =ROUNDDOWN(L13*E6,0) -> 0 | N13: 200121 | O13: =N13/K13 -> 40024.2 | P13: =M13*O13 -> 0
B14: https://www.ic3.gov/Media/PDF/AnnualReport/2020State/StateReport.aspx#?s=47 | C14: Employment | D14: State Victim Count | E14: 298 | F14: =E14/E5 -> 4.3028645e-05 | G14: =ROUNDDOWN(F14*E6,0) -> 7 | H14: 549931 | I14: =H14/E14 -> 1845.406 | J14: =I14*G14 -> 12917.842 | K14: 89 | L14: =K14/E5 -> 1.2850837e-05 | M14: =ROUNDDOWN(L14*E6,0) -> 2 | N14: 520658 | O14: =N14/K14 -> 5850.0899 | P14: =M14*O14 -> 11700.18
B15: https://www.ic3.gov/Media/PDF/AnnualReport/2020State/StateReport.aspx#?s=47 | C15: Extortion | D15: State Victim Count | E15: 1185 | F15: =E15/E5 -> 0.00017110384 | G15: =ROUNDDOWN(F15*E6,0) -> 31 | H15: $287,277 | I15: =H15/E15 -> #VALUE! | J15: =I15*G15 -> #VALUE! | K15: 103 | L15: =K15/E5 -> 1.4872317e-05 | M15: =ROUNDDOWN(L15*E6,0) -> 2 | N15: 12250 | O15: =N15/K15 -> 118.93204 | P15: =M15*O15 -> 237.86408
B16: https://www.ic3.gov/Media/PDF/AnnualReport/2020State/StateReport.aspx#?s=47 | C16: Government Impersonation | D16: State Victim Count | E16: 218 | F16: =E16/E5 -> 3.1477331e-05 | G16: =ROUNDDOWN(F16*E6,0) -> 5 | H16: $301,501 | I16: =H16/E16 -> #VALUE! | J16: =I16*G16 -> #VALUE! | K16: 34 | L16: =K16/E5 -> 4.9093085e-06 | M16: =ROUNDDOWN(L16*E6,0) -> 0 | N16: 95030 | O16: =N16/K16 -> 2795 | P16: =M16*O16 -> 0
B17: https://www.ic3.gov/Media/PDF/AnnualReport/2020State/StateReport.aspx#?s=47 | C17: Harassing/Stalking | D17: State Victim Count | E17: NO MATCH | F17: =E17/E5 -> #VALUE! | G17: =ROUNDDOWN(F17*E6,0) -> #VALUE! | I17: =H17/E17 -> #VALUE! | J17: =I17*G17 -> #VALUE! | L17: =K17/E5 -> 0 | M17: =ROUNDDOWN(L17*E6,0) -> 0 | O17: =N17/K17 -> #DIV/0! | P17: =M17*O17 -> #DIV/0!
B18: https://www.ic3.gov/Media/PDF/AnnualReport/2020State/StateReport.aspx#?s=47 | C18: IPR/Counterfeit | D18: State Victim Count | E18: 75 | F18: =E18/E5 -> 1.0829357e-05 | G18: =ROUNDDOWN(F18*E6,0) -> 1 | H18: 735013 | I18: =H18/E18 -> 9800.1733 | J18: =I18*G18 -> 9800.1733 | K18: 18 | L18: =K18/E5 -> 2.5990457e-06 | M18: =ROUNDDOWN(L18*E6,0) -> 0 | N18: 4516 | O18: =N18/K18 -> 250.88889 | P18: =M18*O18 -> 0
