Workbook

Sheet State Summary Graphs
B2: State IC3 Data
H3: System Intrusion Group | M3: Threat to Personnel via Network | P3: Theft of Data via Network
B4: Year | C4: City Population | D4: Column1 | E4: Column2 | F4: Column3 | G4: Crimes | H4: Data Breach | I4: Personal Data Breach | J4: Malware | K4: Phishing | L4: Ransomware | M4: Crimes Against Children | N4: Extortion | O4: Threats/Stalking/Harassment/Terrorism | P4: IPR/Counterfeit | Q4: Identify Theft | R4: BEC
B5: 2016 | C5: ='2016_IC3 State to City'!$E$6 | H5: 53 | I5: 429 | J5: 60 | K5: 298 | L5: 49 | M5: 14 | N5: 361 | O5: 276 | P5: 44 | Q5: 281 | R5: 161
B6: 2017 | C6: ='2017_IC3 State to City'!$E$6 | H6: 53 | I6: 490 | J6: 43 | K6: 347 | L6: 33 | M6: 19 | N6: 290 | O6: 230 | P6: 38 | Q6: 332 | R6: 184
B7: 2018 | C7: ='2018_IC3 State to City'!$E$6 | H7: 28 | I7: 697 | J7: 23 | K7: 311 | L7: 20 | M7: 28 | N7: 759 | O7: 262 | P7: 25 | Q7: 407 | R7: 297
B8: 2019 | C8: ='2019_IC3 State to City'!$E$6 | H8: 21 | I8: 507 | J8: 46 | K8: 310 | L8: 34 | M8: 23 | N8: 725 | O8: 199 | P8: 58 | Q8: 289 | R8: 331
B9: 2020 | C9: ='2020_IC3 State to City'!$E$6 | H9: 29 | I9: 714 | J9: 18 | K9: 379 | L9: 34 | M9: 60 | N9: 1185 | O9: 267 | P9: 75 | Q9: 419 | R9: 249
B10: 2021 | C10: ='2021_IC3 State to City'!$E$6 | H10: 21 | I10: 742 | J10: 11 | K10: 438 | L10: 47 | M10: 29 | N10: 628 | O10: 172 | P10: 60 | Q10: 529 | R10: 321
B11: 2022 | C11: ='2022_IC3 State to City'!$E$6 | H11: 44 | I11: 903 | J11: 9 | K11: 296 | L11: 31 | M11: 54 | N11: 695 | O11: 28 | P11: 19 | Q11: 539 | R11: ='2022_IC3 State to City'!$E$8

Sheet 2016_IC3 State to City
B4: REF URL | C4: Decription | D4: Unit | E4: Value | F4: Value/State Population | G4: Estimated In-City Victims, 2022, As if IC3 Victim Complaint | H4: State Victim Loss | I4: Even Loss per State Victim Count | J4: Projected In-City Victim Loss | K4: State Subject (Perpetrator) Count | L4: Subject (Perpetrator) to State Population | M4: Estimated Subject to City Population | N4: State Subject Losses (Perpetrator gained X dollars) | O4: Even Loss per State Subject | P4: Estimated In-City Subject Losses (Perpetrator Take from Victim)
B5: https://www.census.gov/quickfacts/fact/table/TN/PST045222 | C5: TN Population in 2016 | D5: Population Estimate | E5: 6646010 | F5: Raw Value | G5: (Victim Count/State Population ) * City Population | J5: Estimated In-City Victims * Even Loss per State Victim | P5: Subject to City * Even Loss per State Subject
B6: https://www.census.gov/quickfacts/chattanoogacitytennessee | C6: Chattanooga Population in 2016 | D6: Population Estimate | E6: 177746
B7: https://www.ic3.gov/Media/PDF/AnnualReport/2016State/StateReport.aspx#?s=47 | C7: Advanced Fee | D7: State Victim Count | E7: 276 | F7: =E7/E5 | G7: =ROUNDDOWN(F7*E6,0) | H7: 1211869 | I7: =H7/E7 | J7: =I7*G7 | K7: 65 | L7: =K7/E5 | M7: =ROUNDDOWN(L7*E6,0) | N7: 147059 | O7: =N7/K7 | P7: =M7*O7
B8: https://www.ic3.gov/Media/PDF/AnnualReport/2016State/StateReport.aspx#?s=47 | C8: Business Email Compromise | D8: State Victim Count | E8: 161 | F8: =E8/E5 | G8: =ROUNDDOWN(F8*E6,0) | H8: 2781785 | I8: =H8/E8 | J8: =I8*G8 | K8: 43 | L8: =K8/E5 | M8: =ROUNDDOWN(L8*E6,0) | N8: 546991 | O8: =N8/K8 | P8: =M8*O8
B9: https://www.ic3.gov/Media/PDF/AnnualReport/2016State/StateReport.aspx#?s=47 | C9: Botnet | D9: State Victim Count | F9: =E9/E5 | G9: =ROUNDDOWN(F9*E6,0) | I9: =H9/E9 | J9: =I9*G9 | L9: =K9/E5 | M9: =ROUNDDOWN(L9*E6,0) | O9: =N9/K9 | P9: =M9*O9
B10: https://www.ic3.gov/Media/PDF/AnnualReport/2016State/StateReport.aspx#?s=47 | C10: Confidence/Romance | D10: State Victim Count | E10: 220 | F10: =E10/E5 | G10: =ROUNDDOWN(F10*E6,0) | H10: 2251140 | I10: =H10/E10 | J10: =I10*G10 | K10: 74 | L10: =K10/E5 | M10: =ROUNDDOWN(L10*E6,0) | N10: 955402 | O10: =N10/K10 | P10: =M10*O10
B11: https://www.ic3.gov/Media/PDF/AnnualReport/2016State/StateReport.aspx#?s=47 | C11: Check Fraud | D11: State Victim Count | F11: =E11/E5 | G11: =ROUNDDOWN(F11*E6,0) | I11: =H11/E11 | J11: =I11*G11 | L11: =K11/E5 | M11: =ROUNDDOWN(L11*E6,0) | O11: =N11/K11 | P11: =M11*O11
B12: https://www.ic3.gov/Media/PDF/AnnualReport/2016State/StateReport.aspx#?s=47 | C12: Crimes Against Children | D12: State Victim Count | E12: 14 | F12: =E12/E5 | G12: =ROUNDDOWN(F12*E6,0) | H12: 175 | I12: =H12/E12 | J12: =I12*G12 | K12: 5 | L12: =K12/E5 | M12: =ROUNDDOWN(L12*E6,0) | N12: 0 | O12: =N12/K12 | P12: =M12*O12
B13: https://www.ic3.gov/Media/PDF/AnnualReport/2016State/StateReport.aspx#?s=47 | C13: Data Breach | D13: State Victim Count | E13: 53 | F13: =E13/E5 | G13: =ROUNDDOWN(F13*E6,0) | H13: 121715 | I13: =H13/E13 | J13: =I13*G13 | K13: 11 | L13: =K13/E5 | M13: =ROUNDDOWN(L13*E6,0) | N13: 35450 | P13: =M13*O13
B14: https://www.ic3.gov/Media/PDF/AnnualReport/2016State/StateReport.aspx#?s=47 | C14: Employment | D14: State Victim Count | E14: 271 | F14: =E14/E5 | G14: =ROUNDDOWN(F14*E6,0) | H14: 513855 | I14: =H14/E14 | J14: =I14*G14 | K14: 75 | L14: =K14/E5 | M14: =ROUNDDOWN(L14*E6,0) | N14: 111690 | O14: =N14/K14 | P14: =M14*O14
B15: https://www.ic3.gov/Media/PDF/AnnualReport/2016State/StateReport.aspx#?s=47 | C15: Extortion | D15: State Victim Count | E15: 361 | F15: =E15/E5 | G15: =ROUNDDOWN(F15*E6,0) | H15: 249043 | I15: =H15/E15 | J15: =I15*G15 | K15: 38 | L15: =K15/E5 | M15: =ROUNDDOWN(L15*E6,0) | N15: 54046 | O15: =N15/K15 | P15: =M15*O15
B16: https://www.ic3.gov/Media/PDF/AnnualReport/2016State/StateReport.aspx#?s=47 | C16: Government Impersonation | D16: State Victim Count | E16: 291 | F16: =E16/E5 | G16: =ROUNDDOWN(F16*E6,0) | H16: 200649 | J16: =I16*G16 | K16: 20 | L16: =K16/E5 | M16: =ROUNDDOWN(L16*E6,0) | N16: 12891 | O16: =N16/K16 | P16: =M16*O16
B17: https://www.ic3.gov/Media/PDF/AnnualReport/2016State/StateReport.aspx#?s=47 | C17: Harassing/Stalking | D17: State Victim Count | F17: =E17/E5 | G17: =ROUNDDOWN(F17*E6,0) | I17: =H17/E17 | J17: =I17*G17 | L17: =K17/E5 | M17: =ROUNDDOWN(L17*E6,0) | O17: =N17/K17 | P17: =M17*O17
B18: https://www.ic3.gov/Media/PDF/AnnualReport/2016State/StateReport.aspx#?s=47 | C18: IPR/Counterfeit | D18: State Victim Count | E18: 44 | F18: =E18/E5 | G18: =ROUNDDOWN(F18*E6,0) | H18: 31909 | I18: =H18/E18 | J18: =I18*G18 | K18: 13 | L18: =K18/E5 | M18: =ROUNDDOWN(L18*E6,0) | N18: 6030 | O18: =N18/K18 | P18: =M18*O18
B19: https://www.ic3.gov/Media/PDF/AnnualReport/2016State/StateReport.aspx#?s=47 | C19: Identity Theft | D19: State Victim Count | E19: 281 | F19: =E19/E5 | G19: =ROUNDDOWN(F19*E6,0) | H19: 564262 | I19: =H19/E19 | J19: =I19*G19 | K19: 77 | L19: =K19/E5 | M19: =ROUNDDOWN(L19*E6,0) | N19: 248422 | O19: =N19/K19 | P19: =M19*O19
B20: https://www.ic3.gov/Media/PDF/AnnualReport/2016State/StateReport.aspx#?s=47 | C20: Investment | D20: State Victim Count | E20: 15 | F20: =E20/E5 | G20: =ROUNDDOWN(F20*E6,0) | H20: 604540 | I20: =H20/E20 | J20: =I20*G20 | K20: 10 | L20: =K20/E5 | M20: =ROUNDDOWN(L20*E6,0) | N20: 377812 | O20: =N20/K20 | P20: =M20*O20
B21: https://www.ic3.gov/Media/PDF/AnnualReport/2016State/StateReport.aspx#?s=47 | C21: Lottery/Sweepstakes/Inheritance | D21: State Victim Count | E21: 102 | F21: =E21/E5 | G21: =ROUNDDOWN(F21*E6,0) | H21: 780297 | I21: =H21/E21 | J21: =I21*G21 | K21: 17 | L21: =K21/E5 | M21: =ROUNDDOWN(L21*E6,0) | N21: 87613 | O21: =N21/K21 | P21: =M21*O21
B22: https://www.ic3.gov/Media/PDF/AnnualReport/2016State/StateReport.aspx#?s=47 | C22: Malware | D22: State Victim Count | E22: 60 | F22: =E22/E5 | G22: =ROUNDDOWN(F22*E6,0) | H22: =8139+7793 | I22: =H22/E22 | J22: =I22*G22 | K22: 14 | L22: =K22/E5 | M22: =ROUNDDOWN(L22*E6,0) | N22: 517 | O22: =N22/K22 | P22: =M22*O22
B23: https://www.ic3.gov/Media/PDF/AnnualReport/2016State/StateReport.aspx#?s=47 | C23: NCDF | D23: State Victim Count | F23: =E23/E5 | G23: =ROUNDDOWN(F23*E6,0) | I23: =H23/E23 | J23: =I23*G23 | L23: =K23/E5 | M23: =ROUNDDOWN(L23*E6,0) | O23: =N23/K23 | P23: =M23*O23
B24: https://www.ic3.gov/Media/PDF/AnnualReport/2016State/StateReport.aspx#?s=47 | C24: NTOC | D24: State Victim Count | F24: =E24/E5 | G24: =ROUNDDOWN(F24*E6,0) | I24: =H24/E24 | J24: =I24*G24 | L24: =K24/E5 | M24: =ROUNDDOWN(L24*E6,0) | O24: =N24/K24 | P24: =M24*O24
B25: https://www.ic3.gov/Media/PDF/AnnualReport/2016State/StateReport.aspx#?s=47 | C25: No Lead Value | D25: State Victim Count | E25: 146 | F25: =E25/E5 | G25: =ROUNDDOWN(F25*E6,0) | H25: 0 | I25: =H25/E25 | J25: =I25*G25 | K25: 215 | L25: =K25/E5 | M25: =ROUNDDOWN(L25*E6,0) | N25: 0 | O25: =N25/K25 | P25: =M25*O25
B26: https://www.ic3.gov/Media/PDF/AnnualReport/2016State/StateReport.aspx#?s=47 | C26: Non-Payable/Non-Delivery | D26: State Victim Count | E26: 1285 | F26: =E26/E5 | G26: =ROUNDDOWN(F26*E6,0) | H26: 1996281 | I26: =H26/E26 | J26: =I26*G26 | K26: 495 | L26: =K26/E5 | M26: =ROUNDDOWN(L26*E6,0) | N26: 1547162 | O26: =N26/K26 | P26: =M26*O26
B27: https://www.ic3.gov/Media/PDF/AnnualReport/2016State/StateReport.aspx#?s=47 | C27: Other | D27: State Victim Count | E27: 148 | F27: =E27/E5 | G27: =ROUNDDOWN(F27*E6,0) | H27: 421656 | I27: =H27/E27 | J27: =I27*G27 | K27: 45 | L27: =K27/E5 | M27: =ROUNDDOWN(L27*E6,0) | N27: 180005 | O27: =N27/K27 | P27: =M27*O27
B28: https://www.ic3.gov/Media/PDF/AnnualReport/2016State/StateReport.aspx#?s=47 | C28: Overpayment | D28: State Victim Count | F28: =E28/E5 | G28: =ROUNDDOWN(F28*E6,0) | H28: NO MATCH | I28: =H28/E28 | J28: =I28*G28 | L28: =K28/E5 | M28: =ROUNDDOWN(L28*E6,0) | O28: =N28/K28 | P28: =M28*O28
B29: https://www.ic3.gov/Media/PDF/AnnualReport/2016State/StateReport.aspx#?s=47 | C29: Personal Data Breach | D29: State Victim Count | E29: 429 | F29: =E29/E5 | G29: =ROUNDDOWN(F29*E6,0) | H29: 938982 | I29: =H29/E29 | J29: =I29*G29 | K29: 282 | L29: =K29/E5 | M29: =ROUNDDOWN(L29*E6,0) | N29: 97512 | O29: =N29/K29 | P29: =M29*O29
B30: https://www.ic3.gov/Media/PDF/AnnualReport/2016State/StateReport.aspx#?s=47 | C30: Phishing | D30: State Victim Count | E30: 298 | F30: =E30/E5 | G30: =ROUNDDOWN(F30*E6,0) | H30: 267275 | I30: =H30/E30 | J30: =I30*G30 | K30: 36 | L30: =K30/E5 | M30: =ROUNDDOWN(L30*E6,0) | N30: 9790 | O30: =N30/K30 | P30: =M30*O30
B31: https://www.ic3.gov/Media/PDF/AnnualReport/2016State/StateReport.aspx#?s=47 | C31: Ransomware | D31: State Victim Count | E31: 49 | F31: =E31/E5 | G31: =ROUNDDOWN(F31*E6,0) | H31: 10106 | I31: =H31/E31 | J31: =I31*G31 | K31: 3 | L31: =K31/E5 | M31: =ROUNDDOWN(L31*E6,0) | N31: 0 | O31: =N31/K31 | P31: =M31*O31
B32: https://www.ic3.gov/Media/PDF/AnnualReport/2016State/StateReport.aspx#?s=47 | C32: Real Estate | D32: State Victim Count | E32: 165 | F32: =E32/E5 | G32: =ROUNDDOWN(F32*E6,0) | H32: 528855 | I32: =H32/E32 | J32: =I32*G32 | K32: 78 | L32: =K32/E5 | M32: =ROUNDDOWN(L32*E6,0) | N32: 459938 | O32: =N32/K32 | P32: =M32*O32
B33: https://www.ic3.gov/Media/PDF/AnnualReport/2016State/StateReport.aspx#?s=47 | C33: SIM Swap | D33: State Victim Count | F33: =E33/E5 | G33: =ROUNDDOWN(F33*E6,0) | H33: NO MATCH | I33: =H33/E33 | J33: =I33*G33 | L33: =K33/E5 | M33: =ROUNDDOWN(L33*E6,0) | O33: =N33/K33 | P33: =M33*O33
B34: https://www.ic3.gov/Media/PDF/AnnualReport/2016State/StateReport.aspx#?s=47 | C34: Spoofing | D34: State Victim Count | F34: =E34/E5 | G34: =ROUNDDOWN(F34*E6,0) | H34: NO MATCH | I34: =H34/E34 | J34: =I34*G34 | K34: 11 | L34: =K34/E5 | M34: =ROUNDDOWN(L34*E6,0) | O34: =N34/K34 | P34: =M34*O34
B35: https://www.ic3.gov/Media/PDF/AnnualReport/2016State/StateReport.aspx#?s=47 | C35: Tech Support | D35: State Victim Count | E35: 185 | F35: =E35/E5 | G35: =ROUNDDOWN(F35*E6,0) | H35: 131727 | I35: =H35/E35 | J35: =I35*G35 | L35: =K35/E5 | M35: =ROUNDDOWN(L35*E6,0) | N35: 2750 | O35: =N35/K35 | P35: =M35*O35
B36: https://www.ic3.gov/Media/PDF/AnnualReport/2016State/StateReport.aspx#?s=47 | C36: Threats of Violence | D36: State Victim Count | E36: 276 | F36: =E36/E5 | G36: =ROUNDDOWN(F36*E6,0) | H36: 227858 | I36: =H36/E36 | J36: =I36*G36 | K36: 283 | L36: =K36/E5 | M36: =ROUNDDOWN(L36*E6,0) | N36: 57874 | O36: =N36/K36 | P36: =M36*O36
J37: =I37*G37
E38: =SUM(E7:E36) | G38: =SUM(G8:G36) | I38: =H38/E38 | J38: =I38*G38
C39: Malware + Virus
C40: Harassment, Stalking, Threats of Violence and Terrorism all combined

Sheet 2017_IC3 State to City
B4: REF URL | C4: Decription | D4: Unit | E4: Value | F4: Value/State Population | G4: Estimated In-City Victims, 2022, As if IC3 Victim Complaint | H4: State Victim Loss | I4: Even Loss per State Victim Count | J4: Projected In-City Victim Loss | K4: State Subject (Perpetrator) Count | L4: Subject (Perpetrator) to State Population | M4: Estimated Subject to City Population | N4: State Subject Losses (Perpetrator gained X dollars) | O4: Even Loss per State Subject | P4: Estimated In-City Subject Losses (Perpetrator Take from Victim)
B5: https://www.census.gov/quickfacts/fact/table/TN/PST045222 | C5: TN Population in 2017 | D5: Population Estimate | E5: 6708799 | F5: Raw Value | G5: (Victim Count/State Population ) * City Population | J5: Estimated In-City Victims * Even Loss per State Victim | P5: Subject to City * Even Loss per State Subject
B6: https://www.census.gov/quickfacts/chattanoogacitytennessee | C6: Chattanooga Population in 2017 | D6: Population Estimate | E6: 179530
B7: https://www.ic3.gov/Media/PDF/AnnualReport/2017State/StateReport.aspx#?s=47 | C7: Advanced Fee | D7: State Victim Count | E7: 264 | F7: =E7/E5 | G7: =ROUNDDOWN(F7*E6,0) | H7: 591748 | I7: =H7/E7 | J7: =I7*G7 | K7: 70 | L7: =K7/E5 | M7: =ROUNDDOWN(L7*E6,0) | N7: 222720 | O7: =N7/K7 | P7: =M7*O7
B8: https://www.ic3.gov/Media/PDF/AnnualReport/2017State/StateReport.aspx#?s=47 | C8: Business Email Compromise | D8: State Victim Count | E8: 184 | F8: =E8/E5 | G8: =ROUNDDOWN(F8*E6,0) | H8: 4251983 | I8: =H8/E8 | J8: =I8*G8 | K8: 44 | L8: =K8/E5 | M8: =ROUNDDOWN(L8*E6,0) | N8: 577018 | O8: =N8/K8 | P8: =M8*O8
B9: https://www.ic3.gov/Media/PDF/AnnualReport/2017State/StateReport.aspx#?s=47 | C9: Botnet | D9: State Victim Count | F9: =E9/E5 | G9: =ROUNDDOWN(F9*E6,0) | I9: =H9/E9 | J9: =I9*G9 | L9: =K9/E5 | M9: =ROUNDDOWN(L9*E6,0) | O9: =N9/K9 | P9: =M9*O9
B10: https://www.ic3.gov/Media/PDF/AnnualReport/2017State/StateReport.aspx#?s=47 | C10: Confidence/Romance | D10: State Victim Count | E10: 260 | F10: =E10/E5 | G10: =ROUNDDOWN(F10*E6,0) | H10: 2450680 | I10: =H10/E10 | J10: =I10*G10 | K10: 88 | L10: =K10/E5 | M10: =ROUNDDOWN(L10*E6,0) | N10: 682875 | O10: =N10/K10 | P10: =M10*O10
B11: https://www.ic3.gov/Media/PDF/AnnualReport/2017State/StateReport.aspx#?s=47 | C11: Check Fraud | D11: State Victim Count | F11: =E11/E5 | G11: =ROUNDDOWN(F11*E6,0) | I11: =H11/E11 | J11: =I11*G11 | L11: =K11/E5 | M11: =ROUNDDOWN(L11*E6,0) | O11: =N11/K11 | P11: =M11*O11
B12: https://www.ic3.gov/Media/PDF/AnnualReport/2017State/StateReport.aspx#?s=47 | C12: Crimes Against Children | D12: State Victim Count | E12: 19 | F12: =E12/E5 | G12: =ROUNDDOWN(F12*E6,0) | H12: 0 | I12: =H12/E12 | J12: =I12*G12 | K12: 3 | L12: =K12/E5 | M12: =ROUNDDOWN(L12*E6,0) | N12: 0 | O12: =N12/K12 | P12: =M12*O12
B13: https://www.ic3.gov/Media/PDF/AnnualReport/2017State/StateReport.aspx#?s=47 | C13: Data Breach | D13: State Victim Count | E13: 53 | F13: =E13/E5 | G13: =ROUNDDOWN(F13*E6,0) | H13: 967932 | I13: =H13/E13 | J13: =I13*G13 | K13: 6 | L13: =K13/E5 | M13: =ROUNDDOWN(L13*E6,0) | N13: 0 | O13: =N13/K13 | P13: =M13*O13
B14: https://www.ic3.gov/Media/PDF/AnnualReport/2017State/StateReport.aspx#?s=47 | C14: Employment | D14: State Victim Count | E14: 257 | F14: =E14/E5 | G14: =ROUNDDOWN(F14*E6,0) | H14: 346353 | I14: =H14/E14 | J14: =I14*G14 | K14: 76 | L14: =K14/E5 | M14: =ROUNDDOWN(L14*E6,0) | N14: 49381 | O14: =N14/K14 | P14: =M14*O14
B15: https://www.ic3.gov/Media/PDF/AnnualReport/2017State/StateReport.aspx#?s=47 | C15: Extortion | D15: State Victim Count | E15: 290 | F15: =E15/E5 | G15: =ROUNDDOWN(F15*E6,0) | H15: 171336 | I15: =H15/E15 | J15: =I15*G15 | K15: 32 | L15: =K15/E5 | M15: =ROUNDDOWN(L15*E6,0) | N15: 10895 | O15: =N15/K15 | P15: =M15*O15
B16: https://www.ic3.gov/Media/PDF/AnnualReport/2017State/StateReport.aspx#?s=47 | C16: Government Impersonation | D16: State Victim Count | E16: 174 | F16: =E16/E5 | G16: =ROUNDDOWN(F16*E6,0) | H16: 118043 | I16: =H16/E16 | J16: =I16*G16 | K16: 11 | L16: =K16/E5 | M16: =ROUNDDOWN(L16*E6,0) | N16: 17516 | O16: =N16/K16 | P16: =M16*O16
B17: https://www.ic3.gov/Media/PDF/AnnualReport/2017State/StateReport.aspx#?s=47 | C17: Harassing/Stalking | D17: State Victim Count | F17: =E17/E5 | G17: =ROUNDDOWN(F17*E6,0) | I17: =H17/E17 | J17: =I17*G17 | L17: =K17/E5 | M17: =ROUNDDOWN(L17*E6,0) | O17: =N17/K17 | P17: =M17*O17
B18: https://www.ic3.gov/Media/PDF/AnnualReport/2017State/StateReport.aspx#?s=47 | C18: IPR/Counterfeit | D18: State Victim Count | E18: 38 | F18: =E18/E5 | G18: =ROUNDDOWN(F18*E6,0) | H18: 34455 | I18: =H18/E18 | J18: =I18*G18 | K18: 12 | L18: =K18/E5 | M18: =ROUNDDOWN(L18*E6,0) | N18: 8398 | O18: =N18/K18 | P18: =M18*O18
B19: https://www.ic3.gov/Media/PDF/AnnualReport/2017State/StateReport.aspx#?s=47 | C19: Identity Theft | D19: State Victim Count | E19: 332 | F19: =E19/E5 | G19: =ROUNDDOWN(F19*E6,0) | H19: 1241184 | I19: =H19/E19 | J19: =I19*G19 | K19: 98 | L19: =K19/E5 | M19: =ROUNDDOWN(L19*E6,0) | N19: 677427 | O19: =N19/K19 | P19: =M19*O19
B20: https://www.ic3.gov/Media/PDF/AnnualReport/2017State/StateReport.aspx#?s=47 | C20: Investment | D20: State Victim Count | E20: 34 | F20: =E20/E5 | G20: =ROUNDDOWN(F20*E6,0) | H20: 260468 | I20: =H20/E20 | J20: =I20*G20 | K20: 16 | L20: =K20/E5 | M20: =ROUNDDOWN(L20*E6,0) | N20: 143560 | O20: =N20/K20 | P20: =M20*O20
B21: https://www.ic3.gov/Media/PDF/AnnualReport/2017State/StateReport.aspx#?s=47 | C21: Lottery/Sweepstakes/Inheritance | D21: State Victim Count | E21: 77 | F21: =E21/E5 | G21: =ROUNDDOWN(F21*E6,0) | H21: 121151 | I21: =H21/E21 | J21: =I21*G21 | K21: 21 | L21: =K21/E5 | M21: =ROUNDDOWN(L21*E6,0) | N21: 83881 | O21: =N21/K21 | P21: =M21*O21
B22: https://www.ic3.gov/Media/PDF/AnnualReport/2017State/StateReport.aspx#?s=47 | C22: Malware | D22: State Victim Count | E22: 43 | F22: =E22/E5 | G22: =ROUNDDOWN(F22*E6,0) | H22: 13325 | I22: =H22/E22 | J22: =I22*G22 | K22: 5 | L22: =K22/E5 | M22: =ROUNDDOWN(L22*E6,0) | N22: 1033 | O22: =N22/K22 | P22: =M22*O22
B23: https://www.ic3.gov/Media/PDF/AnnualReport/2017State/StateReport.aspx#?s=47 | C23: NCDF | D23: State Victim Count | F23: =E23/E5 | G23: =ROUNDDOWN(F23*E6,0) | I23: =H23/E23 | J23: =I23*G23 | L23: =K23/E5 | M23: =ROUNDDOWN(L23*E6,0) | O23: =N23/K23 | P23: =M23*O23
B24: https://www.ic3.gov/Media/PDF/AnnualReport/2017State/StateReport.aspx#?s=47 | C24: NTOC | D24: State Victim Count | F24: =E24/E5 | G24: =ROUNDDOWN(F24*E6,0) | I24: =H24/E24 | J24: =I24*G24 | L24: =K24/E5 | M24: =ROUNDDOWN(L24*E6,0) | O24: =N24/K24 | P24: =M24*O24
B25: https://www.ic3.gov/Media/PDF/AnnualReport/2017State/StateReport.aspx#?s=47 | C25: No Lead Value | D25: State Victim Count | E25: 155 | F25: =E25/E5 | G25: =ROUNDDOWN(F25*E6,0) | H25: 0 | I25: =H25/E25 | J25: =I25*G25 | K25: 157 | L25: =K25/E5 | M25: =ROUNDDOWN(L25*E6,0) | N25: 0 | O25: =N25/K25 | P25: =M25*O25
B26: https://www.ic3.gov/Media/PDF/AnnualReport/2017State/StateReport.aspx#?s=47 | C26: Non-Payable/Non-Delivery | D26: State Victim Count | E26: 1547 | F26: =E26/E5 | G26: =ROUNDDOWN(F26*E6,0) | H26: 2217462 | I26: =H26/E26 | J26: =I26*G26 | K26: 480 | L26: =K26/E5 | M26: =ROUNDDOWN(L26*E6,0) | N26: 906871 | O26: =N26/K26 | P26: =M26*O26
B27: https://www.ic3.gov/Media/PDF/AnnualReport/2017State/StateReport.aspx#?s=47 | C27: Other | D27: State Victim Count | E27: 207 | F27: =E27/E5 | G27: =ROUNDDOWN(F27*E6,0) | H27: 297647 | I27: =H27/E27 | J27: =I27*G27 | K27: 68 | L27: =K27/E5 | M27: =ROUNDDOWN(L27*E6,0) | N27: 6964 | O27: =N27/K27 | P27: =M27*O27
B28: https://www.ic3.gov/Media/PDF/AnnualReport/2017State/StateReport.aspx#?s=47 | C28: Overpayment | D28: State Victim Count | E28: 321 | F28: =E28/E5 | G28: =ROUNDDOWN(F28*E6,0) | H28: 702742 | I28: =H28/E28 | J28: =I28*G28 | K28: 86 | L28: =K28/E5 | M28: =ROUNDDOWN(L28*E6,0) | N28: 92394 | O28: =N28/K28 | P28: =M28*O28
B29: https://www.ic3.gov/Media/PDF/AnnualReport/2017State/StateReport.aspx#?s=47 | C29: Personal Data Breach | D29: State Victim Count | E29: 490 | F29: =E29/E5 | G29: =ROUNDDOWN(F29*E6,0) | H29: 461249 | I29: =H29/E29 | J29: =I29*G29 | K29: 132 | L29: =K29/E5 | M29: =ROUNDDOWN(L29*E6,0) | N29: 180877 | O29: =N29/K29 | P29: =M29*O29
B30: https://www.ic3.gov/Media/PDF/AnnualReport/2017State/StateReport.aspx#?s=47 | C30: Phishing | D30: State Victim Count | E30: 347 | F30: =E30/E5 | G30: =ROUNDDOWN(F30*E6,0) | H30: 133594 | I30: =H30/E30 | J30: =I30*G30 | K30: 57 | L30: =K30/E5 | M30: =ROUNDDOWN(L30*E6,0) | N30: 18601 | O30: =N30/K30 | P30: =M30*O30
B31: https://www.ic3.gov/Media/PDF/AnnualReport/2017State/StateReport.aspx#?s=47 | C31: Ransomware | D31: State Victim Count | E31: 33 | F31: =E31/E5 | G31: =ROUNDDOWN(F31*E6,0) | H31: 95411 | I31: =H31/E31 | J31: =I31*G31 | K31: 2 | L31: =K31/E5 | M31: =ROUNDDOWN(L31*E6,0) | N31: 50000 | O31: =N31/K31 | P31: =M31*O31
B32: https://www.ic3.gov/Media/PDF/AnnualReport/2017State/StateReport.aspx#?s=47 | C32: Real Estate | D32: State Victim Count | E32: 148 | F32: =E32/E5 | G32: =ROUNDDOWN(F32*E6,0) | H32: 262428 | I32: =H32/E32 | J32: =I32*G32 | K32: 78 | L32: =K32/E5 | M32: =ROUNDDOWN(L32*E6,0) | N32: 454840 | O32: =N32/K32 | P32: =M32*O32
B33: https://www.ic3.gov/Media/PDF/AnnualReport/2017State/StateReport.aspx#?s=47 | C33: SIM Swap | D33: State Victim Count | F33: =E33/E5 | G33: =ROUNDDOWN(F33*E6,0) | I33: =H33/E33 | J33: =I33*G33 | L33: =K33/E5 | M33: =ROUNDDOWN(L33*E6,0) | O33: =N33/K33 | P33: =M33*O33
B34: https://www.ic3.gov/Media/PDF/AnnualReport/2017State/StateReport.aspx#?s=47 | C34: Spoofing | D34: State Victim Count | E34: 0 | F34: =E34/E5 | G34: =ROUNDDOWN(F34*E6,0) | H34: 0 | I34: =H34/E34 | J34: =I34*G34 | K34: 0 | L34: =K34/E5 | M34: =ROUNDDOWN(L34*E6,0) | N34: 0 | O34: =N34/K34 | P34: =M34*O34
B35: https://www.ic3.gov/Media/PDF/AnnualReport/2017State/StateReport.aspx#?s=47 | C35: Tech Support | D35: State Victim Count | E35: 190 | F35: =E35/E5 | G35: =ROUNDDOWN(F35*E6,0) | H35: 168911 | I35: =H35/E35 | J35: =I35*G35 | K35: 14 | L35: =K35/E5 | M35: =ROUNDDOWN(L35*E6,0) | N35: 8331 | O35: =N35/K35 | P35: =M35*O35
B36: https://www.ic3.gov/Media/PDF/AnnualReport/2017State/StateReport.aspx#?s=47 | C36: Threats of Violence | D36: State Victim Count | E36: 230 | F36: =E36/E5 | G36: =ROUNDDOWN(F36*E6,0) | H36: 96901 | I36: =H36/E36 | J36: =I36*G36 | K36: 112 | L36: =K36/E5 | M36: =ROUNDDOWN(L36*E6,0) | N36: 98776 | O36: =N36/K36 | P36: =M36*O36
J37: =I37*G37
E38: =SUM(E7:E36) | G38: =SUM(G8:G36) | I38: =H38/E38 | J38: =I38*G38
C40: Harassment, Stalking, Threats of Violence and Terrorism all combined
C41: Had 2 Terrorism this year

Sheet 2018_IC3 State to City
B4: REF URL | C4: Decription | D4: Unit | E4: Value | F4: Value/State Population | G4: Estimated In-City Victims, 2022, As if IC3 Victim Complaint | H4: State Victim Loss | I4: Even Loss per State Victim Count | J4: Projected In-City Victim Loss | K4: State Subject (Perpetrator) Count | L4: Subject (Perpetrator) to State Population | M4: Estimated Subject to City Population | N4: State Subject Losses (Perpetrator gained X dollars) | O4: Even Loss per State Subject | P4: Estimated In-City Subject Losses (Perpetrator Take from Victim)
B5: https://www.census.gov/quickfacts/fact/table/TN/PST045222 | C5: TN Population in 2018 | D5: Population Estimate | E5: 6771631 | F5: Raw Value | G5: (Victim Count/State Population ) * City Population | J5: Estimated In-City Victims * Even Loss per State Victim | P5: Subject to City * Even Loss per State Subject
B6: https://www.census.gov/quickfacts/chattanoogacitytennessee | C6: Chattanooga Population in 2018 | D6: Population Estimate | E6: 181918
B7: https://www.ic3.gov/Media/PDF/AnnualReport/2018State/StateReport.aspx#?s=47 | C7: Advanced Fee | D7: State Victim Count | E7: 275 | F7: =E7/E5 | G7: =ROUNDDOWN(F7*E6,0) | H7: 713685 | I7: =H7/E7 | J7: =I7*G7 | K7: 66 | L7: =K7/E5 | M7: =ROUNDDOWN(L7*E6,0) | N7: 516623 | O7: =N7/K7 | P7: =M7*O7
B8: https://www.ic3.gov/Media/PDF/AnnualReport/2018State/StateReport.aspx#?s=47 | C8: Business Email Compromise | D8: State Victim Count | E8: 297 | F8: =E8/E5 | G8: =ROUNDDOWN(F8*E6,0) | H8: 16072195 | I8: =H8/E8 | J8: =I8*G8 | K8: 59 | L8: =K8/E5 | M8: =ROUNDDOWN(L8*E6,0) | N8: 3628283 | O8: =N8/K8 | P8: =M8*O8
B9: https://www.ic3.gov/Media/PDF/AnnualReport/2018State/StateReport.aspx#?s=47 | C9: Botnet | D9: State Victim Count | F9: =E9/E5 | G9: =ROUNDDOWN(F9*E6,0) | I9: =H9/E9 | J9: =I9*G9 | L9: =K9/E5 | M9: =ROUNDDOWN(L9*E6,0) | O9: =N9/K9 | P9: =M9*O9
B10: https://www.ic3.gov/Media/PDF/AnnualReport/2018State/StateReport.aspx#?s=47 | C10: Confidence/Romance | D10: State Victim Count | E10: 268 | F10: =E10/E5 | G10: =ROUNDDOWN(F10*E6,0) | H10: 5101478 | I10: =H10/E10 | J10: =I10*G10 | K10: 112 | L10: =K10/E5 | M10: =ROUNDDOWN(L10*E6,0) | N10: 2307165 | O10: =N10/K10 | P10: =M10*O10
B11: https://www.ic3.gov/Media/PDF/AnnualReport/2018State/StateReport.aspx#?s=47 | C11: Check Fraud | D11: State Victim Count | F11: =E11/E5 | G11: =ROUNDDOWN(F11*E6,0) | I11: =H11/E11 | J11: =I11*G11 | L11: =K11/E5 | M11: =ROUNDDOWN(L11*E6,0) | O11: =N11/K11 | P11: =M11*O11
B12: https://www.ic3.gov/Media/PDF/AnnualReport/2018State/StateReport.aspx#?s=47 | C12: Crimes Against Children | D12: State Victim Count | E12: 28 | F12: =E12/E5 | G12: =ROUNDDOWN(F12*E6,0) | H12: 0 | I12: =H12/E12 | J12: =I12*G12 | K12: 8 | L12: =K12/E5 | M12: =ROUNDDOWN(L12*E6,0) | N12: 0 | O12: =N12/K12 | P12: =M12*O12
B13: https://www.ic3.gov/Media/PDF/AnnualReport/2018State/StateReport.aspx#?s=47 | C13: Data Breach | D13: State Victim Count | E13: 28 | F13: =E13/E5 | G13: =ROUNDDOWN(F13*E6,0) | H13: 476146 | I13: =H13/E13 | J13: =I13*G13 | K13: 5 | L13: =K13/E5 | M13: =ROUNDDOWN(L13*E6,0) | N13: 126300 | O13: =N13/K13 | P13: =M13*O13
B14: https://www.ic3.gov/Media/PDF/AnnualReport/2018State/StateReport.aspx#?s=47 | C14: Employment | D14: State Victim Count | E14: 258 | F14: =E14/E5 | G14: =ROUNDDOWN(F14*E6,0) | H14: 268247 | I14: =H14/E14 | J14: =I14*G14 | K14: 85 | L14: =K14/E5 | M14: =ROUNDDOWN(L14*E6,0) | N14: 157215 | P14: =M14*O14
B15: https://www.ic3.gov/Media/PDF/AnnualReport/2018State/StateReport.aspx#?s=47 | C15: Extortion | D15: State Victim Count | E15: 759 | F15: =E15/E5 | G15: =ROUNDDOWN(F15*E6,0) | H15: 298202 | I15: =H15/E15 | J15: =I15*G15 | K15: 105 | L15: =K15/E5 | M15: =ROUNDDOWN(L15*E6,0) | N15: 258828 | P15: =M15*O15
B16: https://www.ic3.gov/Media/PDF/AnnualReport/2018State/StateReport.aspx#?s=47 | C16: Government Impersonation | D16: State Victim Count | E16: 236 | F16: =E16/E5 | G16: =ROUNDDOWN(F16*E6,0) | H16: 504683 | J16: =I16*G16 | K16: 24 | L16: =K16/E5 | M16: =ROUNDDOWN(L16*E6,0) | N16: 109665 | O16: =N16/K16 | P16: =M16*O16
B17: https://www.ic3.gov/Media/PDF/AnnualReport/2018State/StateReport.aspx#?s=47 | C17: Harassing/Stalking | D17: State Victim Count | F17: =E17/E5 | G17: =ROUNDDOWN(F17*E6,0) | I17: =H17/E17 | J17: =I17*G17 | L17: =K17/E5 | M17: =ROUNDDOWN(L17*E6,0) | O17: =N17/K17 | P17: =M17*O17
B18: https://www.ic3.gov/Media/PDF/AnnualReport/2018State/StateReport.aspx#?s=47 | C18: IPR/Counterfeit | D18: State Victim Count | E18: 25 | F18: =E18/E5 | G18: =ROUNDDOWN(F18*E6,0) | H18: 62769 | I18: =H18/E18 | J18: =I18*G18 | K18: 10 | L18: =K18/E5 | M18: =ROUNDDOWN(L18*E6,0) | N18: 62431 | P18: =M18*O18
B19: https://www.ic3.gov/Media/PDF/AnnualReport/2018State/StateReport.aspx#?s=47 | C19: Identity Theft | D19: State Victim Count | E19: 407 | F19: =E19/E5 | G19: =ROUNDDOWN(F19*E6,0) | H19: 1271461 | I19: =H19/E19 | J19: =I19*G19 | K19: 235 | L19: =K19/E5 | M19: =ROUNDDOWN(L19*E6,0) | N19: 235577 | O19: =N19/K19 | P19: =M19*O19
B20: https://www.ic3.gov/Media/PDF/AnnualReport/2018State/StateReport.aspx#?s=47 | C20: Investment | D20: State Victim Count | E20: 17 | F20: =E20/E5 | G20: =ROUNDDOWN(F20*E6,0) | H20: 1124651 | I20: =H20/E20 | J20: =I20*G20 | K20: 9 | L20: =K20/E5 | M20: =ROUNDDOWN(L20*E6,0) | N20: 1959171 | O20: =N20/K20 | P20: =M20*O20
B21: https://www.ic3.gov/Media/PDF/AnnualReport/2018State/StateReport.aspx#?s=47 | C21: Lottery/Sweepstakes/Inheritance | D21: State Victim Count | E21: 117 | F21: =E21/E5 | G21: =ROUNDDOWN(F21*E6,0) | H21: 35007 | I21: =H21/E21 | J21: =I21*G21 | K21: 20 | L21: =K21/E5 | M21: =ROUNDDOWN(L21*E6,0) | N21: 185881 | O21: =N21/K21 | P21: =M21*O21
B22: https://www.ic3.gov/Media/PDF/AnnualReport/2018State/StateReport.aspx#?s=47 | C22: Malware | D22: State Victim Count | E22: 23 | F22: =E22/E5 | G22: =ROUNDDOWN(F22*E6,0) | H22: 150 | I22: =H22/E22 | J22: =I22*G22 | K22: 5 | L22: =K22/E5 | M22: =ROUNDDOWN(L22*E6,0) | N22: 1758 | O22: =N22/K22 | P22: =M22*O22
B23: https://www.ic3.gov/Media/PDF/AnnualReport/2018State/StateReport.aspx#?s=47 | C23: NCDF | D23: State Victim Count | F23: =E23/E5 | G23: =ROUNDDOWN(F23*E6,0) | I23: =H23/E23 | J23: =I23*G23 | L23: =K23/E5 | M23: =ROUNDDOWN(L23*E6,0) | O23: =N23/K23 | P23: =M23*O23
B24: https://www.ic3.gov/Media/PDF/AnnualReport/2018State/StateReport.aspx#?s=47 | C24: NTOC | D24: State Victim Count | F24: =E24/E5 | G24: =ROUNDDOWN(F24*E6,0) | I24: =H24/E24 | J24: =I24*G24 | L24: =K24/E5 | M24: =ROUNDDOWN(L24*E6,0) | O24: =N24/K24 | P24: =M24*O24
B25: https://www.ic3.gov/Media/PDF/AnnualReport/2018State/StateReport.aspx#?s=47 | C25: No Lead Value | D25: State Victim Count | E25: 691 | F25: =E25/E5 | G25: =ROUNDDOWN(F25*E6,0) | H25: 2000 | I25: =H25/E25 | J25: =I25*G25 | K25: 501 | L25: =K25/E5 | M25: =ROUNDDOWN(L25*E6,0) | N25: 0 | O25: =N25/K25 | P25: =M25*O25
B26: https://www.ic3.gov/Media/PDF/AnnualReport/2018State/StateReport.aspx#?s=47 | C26: Non-Payable/Non-Delivery | D26: State Victim Count | E26: 1020 | F26: =E26/E5 | G26: =ROUNDDOWN(F26*E6,0) | H26: 2450142 | I26: =H26/E26 | J26: =I26*G26 | K26: 350 | L26: =K26/E5 | M26: =ROUNDDOWN(L26*E6,0) | N26: 1352168 | O26: =N26/K26 | P26: =M26*O26
B27: https://www.ic3.gov/Media/PDF/AnnualReport/2018State/StateReport.aspx#?s=47 | C27: Other | D27: State Victim Count | E27: 146 | F27: =E27/E5 | G27: =ROUNDDOWN(F27*E6,0) | H27: 98342 | I27: =H27/E27 | J27: =I27*G27 | K27: 64 | L27: =K27/E5 | M27: =ROUNDDOWN(L27*E6,0) | N27: 212276 | O27: =N27/K27 | P27: =M27*O27
B28: https://www.ic3.gov/Media/PDF/AnnualReport/2018State/StateReport.aspx#?s=47 | C28: Overpayment | D28: State Victim Count | E28: 228 | F28: =E28/E5 | G28: =ROUNDDOWN(F28*E6,0) | H28: 205197 | I28: =H28/E28 | J28: =I28*G28 | K28: 91 | L28: =K28/E5 | M28: =ROUNDDOWN(L28*E6,0) | N28: 164202 | O28: =N28/K28 | P28: =M28*O28
B29: https://www.ic3.gov/Media/PDF/AnnualReport/2018State/StateReport.aspx#?s=47 | C29: Personal Data Breach | D29: State Victim Count | E29: 697 | F29: =E29/E5 | G29: =ROUNDDOWN(F29*E6,0) | H29: 1078377 | I29: =H29/E29 | J29: =I29*G29 | K29: 187 | L29: =K29/E5 | M29: =ROUNDDOWN(L29*E6,0) | N29: 534473 | O29: =N29/K29 | P29: =M29*O29
B30: https://www.ic3.gov/Media/PDF/AnnualReport/2018State/StateReport.aspx#?s=47 | C30: Phishing | D30: State Victim Count | E30: 311 | F30: =E30/E5 | G30: =ROUNDDOWN(F30*E6,0) | H30: 236437 | I30: =H30/E30 | J30: =I30*G30 | K30: 52 | L30: =K30/E5 | M30: =ROUNDDOWN(L30*E6,0) | N30: 256030 | O30: =N30/K30 | P30: =M30*O30
B31: https://www.ic3.gov/Media/PDF/AnnualReport/2018State/StateReport.aspx#?s=47 | C31: Ransomware | D31: State Victim Count | E31: 20 | F31: =E31/E5 | G31: =ROUNDDOWN(F31*E6,0) | H31: 36722 | I31: =H31/E31 | J31: =I31*G31 | K31: 1 | L31: =K31/E5 | M31: =ROUNDDOWN(L31*E6,0) | N31: 0 | O31: =N31/K31 | P31: =M31*O31
B32: https://www.ic3.gov/Media/PDF/AnnualReport/2018State/StateReport.aspx#?s=47 | C32: Real Estate | D32: State Victim Count | E32: 154 | F32: =E32/E5 | G32: =ROUNDDOWN(F32*E6,0) | H32: 1252773 | I32: =H32/E32 | J32: =I32*G32 | K32: 94 | L32: =K32/E5 | M32: =ROUNDDOWN(L32*E6,0) | N32: 730382 | O32: =N32/K32 | P32: =M32*O32
B33: https://www.ic3.gov/Media/PDF/AnnualReport/2018State/StateReport.aspx#?s=47 | C33: SIM Swap | D33: State Victim Count | F33: =E33/E5 | G33: =ROUNDDOWN(F33*E6,0) | I33: =H33/E33 | J33: =I33*G33 | L33: =K33/E5 | M33: =ROUNDDOWN(L33*E6,0) | O33: =N33/K33 | P33: =M33*O33
B34: https://www.ic3.gov/Media/PDF/AnnualReport/2018State/StateReport.aspx#?s=47 | C34: Spoofing | D34: State Victim Count | E34: 193 | F34: =E34/E5 | G34: =ROUNDDOWN(F34*E6,0) | H34: 297281 | I34: =H34/E34 | J34: =I34*G34 | K34: 40 | L34: =K34/E5 | M34: =ROUNDDOWN(L34*E6,0) | N34: 429686 | O34: =N34/K34 | P34: =M34*O34
B35: https://www.ic3.gov/Media/PDF/AnnualReport/2018State/StateReport.aspx#?s=47 | C35: Tech Support | D35: State Victim Count | E35: 245 | F35: =E35/E5 | G35: =ROUNDDOWN(F35*E6,0) | H35: 405006 | I35: =H35/E35 | J35: =I35*G35 | K35: 28 | L35: =K35/E5 | M35: =ROUNDDOWN(L35*E6,0) | N35: 214280 | O35: =N35/K35 | P35: =M35*O35
B36: https://www.ic3.gov/Media/PDF/AnnualReport/2018State/StateReport.aspx#?s=47 | C36: Threats of Violence | D36: State Victim Count | E36: 262 | F36: =E36/E5 | G36: =ROUNDDOWN(F36*E6,0) | H36: 110608 | I36: =H36/E36 | J36: =I36*G36 | K36: 125 | L36: =K36/E5 | M36: =ROUNDDOWN(L36*E6,0) | N36: 91667 | O36: =N36/K36 | P36: =M36*O36
J37: =I37*G37
E38: =SUM(E7:E36) | G38: =SUM(G8:G36) | I38: =H38/E38 | J38: =I38*G38
C39: Harassment/Stalking/Threats of Violence/Terrorism combined

Sheet 2019_IC3 State to City
B4: REF URL | C4: Decription | D4: Unit | E4: Value | F4: Value/State Population | G4: Estimated In-City Victims, 2022, As if IC3 Victim Complaint | H4: State Victim Loss | I4: Even Loss per State Victim Count | J4: Projected In-City Victim Loss | K4: State Subject (Perpetrator) Count | L4: Subject (Perpetrator) to State Population | M4: Estimated Subject to City Population | N4: State Subject Losses (Perpetrator gained X dollars) | O4: Even Loss per State Subject | P4: Estimated In-City Subject Losses (Perpetrator Take from Victim)
B5: https://www2.census.gov/programs-surveys/popest/tables/2010-2019/state/totals/nst-est2019-01.xlsx | C5: TN Population in 2019 | D5: Population Estimate | E5: 6829174 | F5: Raw Value | G5: (Victim Count/State Population ) * City Population | J5: Estimated In-City Victims * Even Loss per State Victim | P5: Subject to City * Even Loss per State Subject
B6: https://www2.census.gov/programs-surveys/popest/tables/2010-2019/cities/totals/SUB-IP-EST2019-ANNRES-47.xlsx | C6: Chattanooga Population in 2019 | D6: Population Estimate | E6: 182799
B7: https://www.ic3.gov/Media/PDF/AnnualReport/2019State/StateReport.aspx#?s=47 | C7: Advanced Fee | D7: State Victim Count | E7: 213 | F7: =E7/E5 | G7: =ROUNDDOWN(F7*E6,0) | H7: 1071731 | I7: =H7/E7 | J7: =I7*G7 | K7: 50 | L7: =K7/E5 | M7: =ROUNDDOWN(L7*E6,0) | N7: 607608 | O7: =N7/K7 | P7: =M7*O7
B8: https://www.ic3.gov/Media/PDF/AnnualReport/2019State/StateReport.aspx#?s=47 | C8: Business Email Compromise | D8: State Victim Count | E8: 331 | F8: =E8/E5 | G8: =ROUNDDOWN(F8*E6,0) | H8: 12938403 | I8: =H8/E8 | J8: =I8*G8 | K8: 60 | L8: =K8/E5 | M8: =ROUNDDOWN(L8*E6,0) | N8: 7348472 | O8: =N8/K8 | P8: =M8*O8
B9: https://www.ic3.gov/Media/PDF/AnnualReport/2019State/StateReport.aspx#?s=47 | C9: Botnet | D9: State Victim Count | F9: =E9/E5 | G9: =ROUNDDOWN(F9*E6,0) | I9: =H9/E9 | J9: =I9*G9 | L9: =K9/E5 | M9: =ROUNDDOWN(L9*E6,0) | O9: =N9/K9 | P9: =M9*O9
B10: https://www.ic3.gov/Media/PDF/AnnualReport/2019State/StateReport.aspx#?s=47 | C10: Confidence/Romance | D10: State Victim Count | E10: 293 | F10: =E10/E5 | G10: =ROUNDDOWN(F10*E6,0) | H10: 4948521 | I10: =H10/E10 | J10: =I10*G10 | K10: 131 | L10: =K10/E5 | M10: =ROUNDDOWN(L10*E6,0) | N10: 2571226 | O10: =N10/K10 | P10: =M10*O10
B11: https://www.ic3.gov/Media/PDF/AnnualReport/2019State/StateReport.aspx#?s=47 | C11: Check Fraud | D11: State Victim Count | F11: =E11/E5 | G11: =ROUNDDOWN(F11*E6,0) | I11: =H11/E11 | J11: =I11*G11 | L11: =K11/E5 | M11: =ROUNDDOWN(L11*E6,0) | O11: =N11/K11 | P11: =M11*O11
B12: https://www.ic3.gov/Media/PDF/AnnualReport/2019State/StateReport.aspx#?s=47 | C12: Crimes Against Children | D12: State Victim Count | E12: 23 | F12: =E12/E5 | G12: =ROUNDDOWN(F12*E6,0) | H12: 0 | I12: =H12/E12 | J12: =I12*G12 | K12: 5 | L12: =K12/E5 | M12: =ROUNDDOWN(L12*E6,0) | N12: 0 | O12: =N12/K12 | P12: =M12*O12
B13: https://www.ic3.gov/Media/PDF/AnnualReport/2019State/StateReport.aspx#?s=47 | C13: Data Breach | D13: State Victim Count | E13: 21 | F13: =E13/E5 | G13: =ROUNDDOWN(F13*E6,0) | H13: 2572 | I13: =H13/E13 | J13: =I13*G13 | K13: 1 | L13: =K13/E5 | M13: =ROUNDDOWN(L13*E6,0) | N13: 0 | O13: =N13/K13 | P13: =M13*O13
B14: https://www.ic3.gov/Media/PDF/AnnualReport/2019State/StateReport.aspx#?s=47 | C14: Employment | D14: State Victim Count | E14: 208 | F14: =E14/E5 | G14: =ROUNDDOWN(F14*E6,0) | H14: 394010 | I14: =H14/E14 | J14: =I14*G14 | K14: 64 | L14: =K14/E5 | M14: =ROUNDDOWN(L14*E6,0) | N14: 208089 | O14: =N14/K14 | P14: =M14*O14
B15: https://www.ic3.gov/Media/PDF/AnnualReport/2019State/StateReport.aspx#?s=47 | C15: Extortion | D15: State Victim Count | E15: 725 | F15: =E15/E5 | G15: =ROUNDDOWN(F15*E6,0) | H15: 629565 | J15: =I15*G15 | K15: 93 | L15: =K15/E5 | M15: =ROUNDDOWN(L15*E6,0) | N15: 87152 | O15: =N15/K15 | P15: =M15*O15
B16: https://www.ic3.gov/Media/PDF/AnnualReport/2019State/StateReport.aspx#?s=47 | C16: Government Impersonation | D16: State Victim Count | E16: 227 | F16: =E16/E5 | G16: =ROUNDDOWN(F16*E6,0) | H16: 555364 | I16: =H16/E16 | J16: =I16*G16 | K16: 29 | L16: =K16/E5 | M16: =ROUNDDOWN(L16*E6,0) | N16: 83100 | O16: =N16/K16 | P16: =M16*O16
B17: https://www.ic3.gov/Media/PDF/AnnualReport/2019State/StateReport.aspx#?s=47 | C17: Harassing/Stalking | D17: State Victim Count | F17: =E17/E5 | G17: =ROUNDDOWN(F17*E6,0) | I17: =H17/E17 | J17: =I17*G17 | L17: =K17/E5 | M17: =ROUNDDOWN(L17*E6,0) | O17: =N17/K17 | P17: =M17*O17
B18: https://www.ic3.gov/Media/PDF/AnnualReport/2019State/StateReport.aspx#?s=47 | C18: IPR/Counterfeit | D18: State Victim Count | E18: 58 | F18: =E18/E5 | G18: =ROUNDDOWN(F18*E6,0) | H18: 195407 | I18: =H18/E18 | J18: =I18*G18 | K18: 8 | L18: =K18/E5 | M18: =ROUNDDOWN(L18*E6,0) | N18: 2925 | O18: =N18/K18 | P18: =M18*O18
B19: https://www.ic3.gov/Media/PDF/AnnualReport/2019State/StateReport.aspx#?s=47 | C19: Identity Theft | D19: State Victim Count | E19: 289 | F19: =E19/E5 | G19: =ROUNDDOWN(F19*E6,0) | H19: 896835 | I19: =H19/E19 | J19: =I19*G19 | K19: 91 | L19: =K19/E5 | M19: =ROUNDDOWN(L19*E6,0) | N19: 392223 | O19: =N19/K19 | P19: =M19*O19
B20: https://www.ic3.gov/Media/PDF/AnnualReport/2019State/StateReport.aspx#?s=47 | C20: Investment | D20: State Victim Count | E20: 35 | F20: =E20/E5 | G20: =ROUNDDOWN(F20*E6,0) | H20: 7667267 | I20: =H20/E20 | J20: =I20*G20 | K20: 25 | L20: =K20/E5 | M20: =ROUNDDOWN(L20*E6,0) | N20: 515037 | O20: =N20/K20 | P20: =M20*O20
B21: https://www.ic3.gov/Media/PDF/AnnualReport/2019State/StateReport.aspx#?s=47 | C21: Lottery/Sweepstakes/Inheritance | D21: State Victim Count | E21: 113 | F21: =E21/E5 | G21: =ROUNDDOWN(F21*E6,0) | H21: 595993 | I21: =H21/E21 | J21: =I21*G21 | K21: 18 | L21: =K21/E5 | M21: =ROUNDDOWN(L21*E6,0) | N21: 1168782 | O21: =N21/K21 | P21: =M21*O21
B22: https://www.ic3.gov/Media/PDF/AnnualReport/2019State/StateReport.aspx#?s=47 | C22: Malware | D22: State Victim Count | E22: 46 | F22: =E22/E5 | G22: =ROUNDDOWN(F22*E6,0) | H22: 707 | I22: =H22/E22 | J22: =I22*G22 | K22: 5 | L22: =K22/E5 | M22: =ROUNDDOWN(L22*E6,0) | N22: 0 | O22: =N22/K22 | P22: =M22*O22
B23: https://www.ic3.gov/Media/PDF/AnnualReport/2019State/StateReport.aspx#?s=47 | C23: NCDF | D23: State Victim Count | F23: =E23/E5 | G23: =ROUNDDOWN(F23*E6,0) | I23: =H23/E23 | J23: =I23*G23 | L23: =K23/E5 | M23: =ROUNDDOWN(L23*E6,0) | O23: =N23/K23 | P23: =M23*O23
B24: https://www.ic3.gov/Media/PDF/AnnualReport/2019State/StateReport.aspx#?s=47 | C24: NTOC | D24: State Victim Count | F24: =E24/E5 | G24: =ROUNDDOWN(F24*E6,0) | I24: =H24/E24 | J24: =I24*G24 | L24: =K24/E5 | M24: =ROUNDDOWN(L24*E6,0) | O24: =N24/K24 | P24: =M24*O24
B25: https://www.ic3.gov/Media/PDF/AnnualReport/2019State/StateReport.aspx#?s=47 | C25: No Lead Value | D25: State Victim Count | E25: 629 | F25: =E25/E5 | G25: =ROUNDDOWN(F25*E6,0) | H25: 0 | I25: =H25/E25 | J25: =I25*G25 | K25: 746 | L25: =K25/E5 | M25: =ROUNDDOWN(L25*E6,0) | N25: 0 | O25: =N25/K25 | P25: =M25*O25
B26: https://www.ic3.gov/Media/PDF/AnnualReport/2019State/StateReport.aspx#?s=47 | C26: Non-Payable/Non-Delivery | D26: State Victim Count | E26: 1067 | F26: =E26/E5 | G26: =ROUNDDOWN(F26*E6,0) | H26: 1641120 | I26: =H26/E26 | J26: =I26*G26 | K26: 404 | L26: =K26/E5 | M26: =ROUNDDOWN(L26*E6,0) | N26: 807007 | O26: =N26/K26 | P26: =M26*O26
B27: https://www.ic3.gov/Media/PDF/AnnualReport/2019State/StateReport.aspx#?s=47 | C27: Other | D27: State Victim Count | E27: 83 | F27: =E27/E5 | G27: =ROUNDDOWN(F27*E6,0) | H27: 629450 | I27: =H27/E27 | J27: =I27*G27 | K27: 34 | L27: =K27/E5 | M27: =ROUNDDOWN(L27*E6,0) | N27: 827641 | O27: =N27/K27 | P27: =M27*O27
B28: https://www.ic3.gov/Media/PDF/AnnualReport/2019State/StateReport.aspx#?s=47 | C28: Overpayment | D28: State Victim Count | E28: 222 | F28: =E28/E5 | G28: =ROUNDDOWN(F28*E6,0) | H28: 826044 | I28: =H28/E28 | J28: =I28*G28 | K28: 97 | L28: =K28/E5 | M28: =ROUNDDOWN(L28*E6,0) | N28: 428273 | O28: =N28/K28 | P28: =M28*O28
B29: https://www.ic3.gov/Media/PDF/AnnualReport/2019State/StateReport.aspx#?s=47 | C29: Personal Data Breach | D29: State Victim Count | E29: 507 | F29: =E29/E5 | G29: =ROUNDDOWN(F29*E6,0) | H29: 750727 | I29: =H29/E29 | J29: =I29*G29 | K29: 147 | L29: =K29/E5 | M29: =ROUNDDOWN(L29*E6,0) | N29: 278229 | O29: =N29/K29 | P29: =M29*O29
B30: https://www.ic3.gov/Media/PDF/AnnualReport/2019State/StateReport.aspx#?s=47 | C30: Phishing | D30: State Victim Count | E30: 310 | F30: =E30/E5 | G30: =ROUNDDOWN(F30*E6,0) | H30: 127466 | I30: =H30/E30 | J30: =I30*G30 | K30: 51 | L30: =K30/E5 | M30: =ROUNDDOWN(L30*E6,0) | N30: 57192 | O30: =N30/K30 | P30: =M30*O30
B31: https://www.ic3.gov/Media/PDF/AnnualReport/2019State/StateReport.aspx#?s=47 | C31: Ransomware | D31: State Victim Count | E31: 34 | F31: =E31/E5 | G31: =ROUNDDOWN(F31*E6,0) | H31: 16325 | I31: =H31/E31 | J31: =I31*G31 | K31: 4 | L31: =K31/E5 | M31: =ROUNDDOWN(L31*E6,0) | N31: 200 | O31: =N31/K31 | P31: =M31*O31
B32: https://www.ic3.gov/Media/PDF/AnnualReport/2019State/StateReport.aspx#?s=47 | C32: Real Estate | D32: State Victim Count | E32: 144 | F32: =E32/E5 | G32: =ROUNDDOWN(F32*E6,0) | H32: 1090182 | I32: =H32/E32 | J32: =I32*G32 | K32: 76 | L32: =K32/E5 | M32: =ROUNDDOWN(L32*E6,0) | N32: 4483062 | O32: =N32/K32 | P32: =M32*O32
B33: https://www.ic3.gov/Media/PDF/AnnualReport/2019State/StateReport.aspx#?s=47 | C33: SIM Swap | D33: State Victim Count | F33: =E33/E5 | G33: =ROUNDDOWN(F33*E6,0) | I33: =H33/E33 | J33: =I33*G33 | L33: =K33/E5 | M33: =ROUNDDOWN(L33*E6,0) | O33: =N33/K33 | P33: =M33*O33
B34: https://www.ic3.gov/Media/PDF/AnnualReport/2019State/StateReport.aspx#?s=47 | C34: Spoofing | D34: State Victim Count | E34: 343 | F34: =E34/E5 | G34: =ROUNDDOWN(F34*E6,0) | H34: 3477664 | I34: =H34/E34 | J34: =I34*G34 | K34: 72 | L34: =K34/E5 | M34: =ROUNDDOWN(L34*E6,0) | N34: 689474 | O34: =N34/K34 | P34: =M34*O34
B35: https://www.ic3.gov/Media/PDF/AnnualReport/2019State/StateReport.aspx#?s=47 | C35: Tech Support | D35: State Victim Count | E35: 232 | F35: =E35/E5 | G35: =ROUNDDOWN(F35*E6,0) | H35: 729247 | I35: =H35/E35 | J35: =I35*G35 | K35: 29 | L35: =K35/E5 | M35: =ROUNDDOWN(L35*E6,0) | N35: 49275 | O35: =N35/K35 | P35: =M35*O35
B36: https://www.ic3.gov/Media/PDF/AnnualReport/2019State/StateReport.aspx#?s=47 | C36: Threats of Violence | D36: State Victim Count | E36: 199 | F36: =E36/E5 | G36: =ROUNDDOWN(F36*E6,0) | H36: 18762 | I36: =H36/E36 | J36: =I36*G36 | K36: 120 | L36: =K36/E5 | M36: =ROUNDDOWN(L36*E6,0) | N36: 119327 | O36: =N36/K36 | P36: =M36*O36
J37: =I37*G37
E38: =SUM(E7:E36) | G38: =SUM(G8:G36) | I38: =H38/E38 | J38: =I38*G38
C40: Stalking/Harassment and Threats of violence were combined with Terrorism
C41: Shown here as Threats of Violence, as with others.

Sheet 2020_IC3 State to City
B4: REF URL | C4: Decription | D4: Unit | E4: Value | F4: Value/State Population | G4: Estimated In-City Victims, 2022, As if IC3 Victim Complaint | H4: State Victim Loss | I4: Even Loss per State Victim Count | J4: Projected In-City Victim Loss | K4: State Subject (Perpetrator) Count | L4: Subject (Perpetrator) to State Population | M4: Estimated Subject to City Population | N4: State Subject Losses (Perpetrator gained X dollars) | O4: Even Loss per State Subject | P4: Estimated In-City Subject Losses (Perpetrator Take from Victim)
B5: https://www2.census.gov/programs-surveys/popest/datasets/2020-2022/state/totals/NST-EST2022-POPCHG2020_2022.csv | C5: TN Population in 2020 | D5: Population Estimate | E5: 6925619 | F5: Raw Value | G5: (Victim Count/State Population ) * City Population | J5: Estimated In-City Victims * Even Loss per State Victim | P5: Subject to City * Even Loss per State Subject
B6: https://www.census.gov/data/tables/time-series/demo/popest/2020s-total-cities-and-towns.html | C6: Chattanooga Population in 2020 | D6: Population Estimate | E6: 181560
B7: https://www.ic3.gov/Media/PDF/AnnualReport/2020State/StateReport.aspx#?s=47 | C7: Advanced Fee | D7: State Victim Count | E7: 219 | F7: =E7/E5 | G7: =ROUNDDOWN(F7*E6,0) | H7: 563344 | I7: =H7/E7 | J7: =I7*G7 | K7: 57 | L7: =K7/E5 | M7: =ROUNDDOWN(L7*E6,0) | N7: 147490 | O7: =N7/K7 | P7: =M7*O7
B8: https://www.ic3.gov/Media/PDF/AnnualReport/2020State/StateReport.aspx#?s=47 | C8: Business Email Compromise | D8: State Victim Count | E8: 249 | F8: =E8/E5 | G8: =ROUNDDOWN(F8*E6,0) | H8: 20831147 | I8: =H8/E8 | J8: =I8*G8 | K8: 41 | L8: =K8/E5 | M8: =ROUNDDOWN(L8*E6,0) | N8: 3163786 | O8: =N8/K8 | P8: =M8*O8
B9: https://www.ic3.gov/Media/PDF/AnnualReport/2020State/StateReport.aspx#?s=47 | C9: Botnet | D9: State Victim Count | E9: NO MATCH | F9: =E9/E5 | G9: =ROUNDDOWN(F9*E6,0) | I9: =H9/E9 | J9: =I9*G9 | L9: =K9/E5 | M9: =ROUNDDOWN(L9*E6,0) | O9: =N9/K9 | P9: =M9*O9
B10: https://www.ic3.gov/Media/PDF/AnnualReport/2020State/StateReport.aspx#?s=47 | C10: Confidence/Romance | D10: State Victim Count | E10: 334 | F10: =E10/E5 | G10: =ROUNDDOWN(F10*E6,0) | H10: 4526218 | I10: =H10/E10 | J10: =I10*G10 | K10: 119 | L10: =K10/E5 | M10: =ROUNDDOWN(L10*E6,0) | N10: 2617420 | O10: =N10/K10 | P10: =M10*O10
B11: https://www.ic3.gov/Media/PDF/AnnualReport/2020State/StateReport.aspx#?s=47 | C11: Check Fraud | D11: State Victim Count | E11: NO MATCH | F11: =E11/E5 | G11: =ROUNDDOWN(F11*E6,0) | I11: =H11/E11 | J11: =I11*G11 | L11: =K11/E5 | M11: =ROUNDDOWN(L11*E6,0) | O11: =N11/K11 | P11: =M11*O11
B12: https://www.ic3.gov/Media/PDF/AnnualReport/2020State/StateReport.aspx#?s=47 | C12: Crimes Against Children | D12: State Victim Count | E12: 60 | F12: =E12/E5 | G12: =ROUNDDOWN(F12*E6,0) | H12: 0 | I12: =H12/E12 | J12: =I12*G12 | K12: 12 | L12: =K12/E5 | M12: =ROUNDDOWN(L12*E6,0) | N12: 0 | O12: =N12/K12 | P12: =M12*O12
B13: https://www.ic3.gov/Media/PDF/AnnualReport/2020State/StateReport.aspx#?s=47 | C13: Data Breach | D13: State Victim Count | E13: 29 | F13: =E13/E5 | G13: =ROUNDDOWN(F13*E6,0) | H13: 1227717 | I13: =H13/E13 | J13: =I13*G13 | K13: 5 | L13: =K13/E5 | M13: =ROUNDDOWN(L13*E6,0) | N13: 200121 | O13: =N13/K13 | P13: =M13*O13
B14: https://www.ic3.gov/Media/PDF/AnnualReport/2020State/StateReport.aspx#?s=47 | C14: Employment | D14: State Victim Count | E14: 298 | F14: =E14/E5 | G14: =ROUNDDOWN(F14*E6,0) | H14: 549931 | I14: =H14/E14 | J14: =I14*G14 | K14: 89 | L14: =K14/E5 | M14: =ROUNDDOWN(L14*E6,0) | N14: 520658 | O14: =N14/K14 | P14: =M14*O14
B15: https://www.ic3.gov/Media/PDF/AnnualReport/2020State/StateReport.aspx#?s=47 | C15: Extortion | D15: State Victim Count | E15: 1185 | F15: =E15/E5 | G15: =ROUNDDOWN(F15*E6,0) | H15: $287,277 | I15: =H15/E15 | J15: =I15*G15 | K15: 103 | L15: =K15/E5 | M15: =ROUNDDOWN(L15*E6,0) | N15: 12250 | O15: =N15/K15 | P15: =M15*O15
B16: https://www.ic3.gov/Media/PDF/AnnualReport/2020State/StateReport.aspx#?s=47 | C16: Government Impersonation | D16: State Victim Count | E16: 218 | F16: =E16/E5 | G16: =ROUNDDOWN(F16*E6,0) | H16: $301,501 | I16: =H16/E16 | J16: =I16*G16 | K16: 34 | L16: =K16/E5 | M16: =ROUNDDOWN(L16*E6,0) | N16: 95030 | O16: =N16/K16 | P16: =M16*O16
B17: https://www.ic3.gov/Media/PDF/AnnualReport/2020State/StateReport.aspx#?s=47 | C17: Harassing/Stalking | D17: State Victim Count | E17: NO MATCH | F17: =E17/E5 | G17: =ROUNDDOWN(F17*E6,0) | I17: =H17/E17 | J17: =I17*G17 | L17: =K17/E5 | M17: =ROUNDDOWN(L17*E6,0) | O17: =N17/K17 | P17: =M17*O17
B18: https://www.ic3.gov/Media/PDF/AnnualReport/2020State/StateReport.aspx#?s=47 | C18: IPR/Counterfeit | D18: State Victim Count | E18: 75 | F18: =E18/E5 | G18: =ROUNDDOWN(F18*E6,0) | H18: 735013 | I18: =H18/E18 | J18: =I18*G18 | K18: 18 | L18: =K18/E5 | M18: =ROUNDDOWN(L18*E6,0) | N18: 4516 | O18: =N18/K18 | P18: =M18*O18
B19: https://www.ic3.gov/Media/PDF/AnnualReport/2020State/StateReport.aspx#?s=47 | C19: Identity Theft | D19: State Victim Count | E19: 419 | F19: =E19/E5 | G19: =ROUNDDOWN(F19*E6,0) | H19: 1024515 | I19: =H19/E19 | J19: =I19*G19 | K19: 120 | L19: =K19/E5 | M19: =ROUNDDOWN(L19*E6,0) | N19: 144969 | O19: =N19/K19 | P19: =M19*O19
B20: https://www.ic3.gov/Media/PDF/AnnualReport/2020State/StateReport.aspx#?s=47 | C20: Investment | D20: State Victim Count | E20: 71 | F20: =E20/E5 | G20: =ROUNDDOWN(F20*E6,0) | H20: 4465348 | I20: =H20/E20 | J20: =I20*G20 | K20: 14 | L20: =K20/E5 | M20: =ROUNDDOWN(L20*E6,0) | N20: 423449 | O20: =N20/K20 | P20: =M20*O20
B21: https://www.ic3.gov/Media/PDF/AnnualReport/2020State/StateReport.aspx#?s=47 | C21: Lottery/Sweepstakes/Inheritance | D21: State Victim Count | E21: 130 | F21: =E21/E5 | G21: =ROUNDDOWN(F21*E6,0) | H21: 798607 | I21: =H21/E21 | J21: =I21*G21 | K21: 19 | L21: =K21/E5 | M21: =ROUNDDOWN(L21*E6,0) | N21: 142442 | O21: =N21/K21 | P21: =M21*O21
B22: https://www.ic3.gov/Media/PDF/AnnualReport/2020State/StateReport.aspx#?s=47 | C22: Malware | D22: State Victim Count | E22: 18 | F22: =E22/E5 | G22: =ROUNDDOWN(F22*E6,0) | H22: 7696 | I22: =H22/E22 | J22: =I22*G22 | K22: 3 | L22: =K22/E5 | M22: =ROUNDDOWN(L22*E6,0) | N22: 0 | O22: =N22/K22 | P22: =M22*O22
B23: https://www.ic3.gov/Media/PDF/AnnualReport/2020State/StateReport.aspx#?s=47 | C23: NCDF | D23: State Victim Count | E23: NO MATCH | F23: =E23/E5 | G23: =ROUNDDOWN(F23*E6,0) | I23: =H23/E23 | J23: =I23*G23 | L23: =K23/E5 | M23: =ROUNDDOWN(L23*E6,0) | O23: =N23/K23 | P23: =M23*O23
B24: https://www.ic3.gov/Media/PDF/AnnualReport/2020State/StateReport.aspx#?s=47 | C24: NTOC | D24: State Victim Count | E24: NO MATCH | F24: =E24/E5 | G24: =ROUNDDOWN(F24*E6,0) | I24: =H24/E24 | J24: =I24*G24 | L24: =K24/E5 | M24: =ROUNDDOWN(L24*E6,0) | O24: =N24/K24 | P24: =M24*O24
B25: https://www.ic3.gov/Media/PDF/AnnualReport/2020State/StateReport.aspx#?s=47 | C25: No Lead Value | D25: State Victim Count | E25: 843 | F25: =E25/E5 | G25: =ROUNDDOWN(F25*E6,0) | H25: 0 | I25: =H25/E25 | J25: =I25*G25 | K25: 693 | L25: =K25/E5 | M25: =ROUNDDOWN(L25*E6,0) | N25: 0 | O25: =N25/K25 | P25: =M25*O25
B26: https://www.ic3.gov/Media/PDF/AnnualReport/2020State/StateReport.aspx#?s=47 | C26: Non-Payable/Non-Delivery | D26: State Victim Count | E26: 1922 | F26: =E26/E5 | G26: =ROUNDDOWN(F26*E6,0) | H26: 2347435 | I26: =H26/E26 | J26: =I26*G26 | K26: 543 | L26: =K26/E5 | M26: =ROUNDDOWN(L26*E6,0) | N26: 3447980 | O26: =N26/K26 | P26: =M26*O26
B27: https://www.ic3.gov/Media/PDF/AnnualReport/2020State/StateReport.aspx#?s=47 | C27: Other | D27: State Victim Count | E27: 110 | F27: =E27/E5 | G27: =ROUNDDOWN(F27*E6,0) | H27: 431446 | I27: =H27/E27 | J27: =I27*G27 | K27: 38 | L27: =K27/E5 | M27: =ROUNDDOWN(L27*E6,0) | N27: 483231 | O27: =N27/K27 | P27: =M27*O27
B28: https://www.ic3.gov/Media/PDF/AnnualReport/2020State/StateReport.aspx#?s=47 | C28: Overpayment | D28: State Victim Count | E28: 162 | F28: =E28/E5 | G28: =ROUNDDOWN(F28*E6,0) | H28: 319136 | I28: =H28/E28 | J28: =I28*G28 | K28: 59 | L28: =K28/E5 | M28: =ROUNDDOWN(L28*E6,0) | N28: 137685 | O28: =N28/K28 | P28: =M28*O28
B29: https://www.ic3.gov/Media/PDF/AnnualReport/2020State/StateReport.aspx#?s=47 | C29: Personal Data Breach | D29: State Victim Count | E29: 714 | F29: =E29/E5 | G29: =ROUNDDOWN(F29*E6,0) | H29: 569494 | I29: =H29/E29 | J29: =I29*G29 | K29: 215 | L29: =K29/E5 | M29: =ROUNDDOWN(L29*E6,0) | N29: 118928 | O29: =N29/K29 | P29: =M29*O29
B30: https://www.ic3.gov/Media/PDF/AnnualReport/2020State/StateReport.aspx#?s=47 | C30: Phishing | D30: State Victim Count | E30: 379 | F30: =E30/E5 | G30: =ROUNDDOWN(F30*E6,0) | H30: 2921163 | I30: =H30/E30 | J30: =I30*G30 | K30: 42 | L30: =K30/E5 | M30: =ROUNDDOWN(L30*E6,0) | N30: 173343 | O30: =N30/K30 | P30: =M30*O30
B31: https://www.ic3.gov/Media/PDF/AnnualReport/2020State/StateReport.aspx#?s=47 | C31: Ransomware | D31: State Victim Count | E31: 34 | F31: =E31/E5 | G31: =ROUNDDOWN(F31*E6,0) | H31: 24860 | I31: =H31/E31 | J31: =I31*G31 | K31: 0 | L31: =K31/E5 | M31: =ROUNDDOWN(L31*E6,0) | N31: 0 | O31: =N31/K31 | P31: =M31*O31
B32: https://www.ic3.gov/Media/PDF/AnnualReport/2020State/StateReport.aspx#?s=47 | C32: Real Estate | D32: State Victim Count | E32: 229 | F32: =E32/E5 | G32: =ROUNDDOWN(F32*E6,0) | H32: 2382094 | I32: =H32/E32 | J32: =I32*G32 | K32: 67 | L32: =K32/E5 | M32: =ROUNDDOWN(L32*E6,0) | N32: 464575 | O32: =N32/K32 | P32: =M32*O32
B33: https://www.ic3.gov/Media/PDF/AnnualReport/2020State/StateReport.aspx#?s=47 | C33: SIM Swap | D33: State Victim Count | E33: NO MATCH | F33: =E33/E5 | G33: =ROUNDDOWN(F33*E6,0) | I33: =H33/E33 | J33: =I33*G33 | L33: =K33/E5 | M33: =ROUNDDOWN(L33*E6,0) | O33: =N33/K33 | P33: =M33*O33
B34: https://www.ic3.gov/Media/PDF/AnnualReport/2020State/StateReport.aspx#?s=47 | C34: Spoofing | D34: State Victim Count | E34: 366 | F34: =E34/E5 | G34: =ROUNDDOWN(F34*E6,0) | H34: 3299698 | I34: =H34/E34 | J34: =I34*G34 | K34: 72 | L34: =K34/E5 | M34: =ROUNDDOWN(L34*E6,0) | N34: 233490 | O34: =N34/K34 | P34: =M34*O34
B35: https://www.ic3.gov/Media/PDF/AnnualReport/2020State/StateReport.aspx#?s=47 | C35: Tech Support | D35: State Victim Count | E35: 281 | F35: =E35/E5 | G35: =ROUNDDOWN(F35*E6,0) | H35: 1500271 | I35: =H35/E35 | J35: =I35*G35 | K35: 47 | L35: =K35/E5 | M35: =ROUNDDOWN(L35*E6,0) | N35: 151959 | O35: =N35/K35 | P35: =M35*O35
B36: https://www.ic3.gov/Media/PDF/AnnualReport/2020State/StateReport.aspx#?s=47 | C36: Threats of Violence | D36: State Victim Count | E36: 267 | F36: =E36/E5 | G36: =ROUNDDOWN(F36*E6,0) | H36: 38329 | I36: =H36/E36 | J36: =I36*G36 | K36: 109 | L36: =K36/E5 | M36: =ROUNDDOWN(L36*E6,0) | N36: 1426 | O36: =N36/K36 | P36: =M36*O36
J37: =I37*G37
E38: =SUM(E7:E36) | G38: =SUM(G8:G36) | I38: =H38/E38 | J38: =I38*G38
C39: Reported harassment and threats of violence together
C40: Put the value under threats of violence
O41: Looking at these numbers on local losses,
O42: It seems that in order to make millions,
O43: cybercriminals might have to work globally.

Sheet 2021_IC3 State to City
B4: REF URL | C4: Decription | D4: Unit | E4: Value | F4: Value/State Population | G4: Estimated In-City Victims, 2022, As if IC3 Victim Complaint | H4: State Victim Loss | I4: Even Loss per State Victim Count | J4: Projected In-City Victim Loss | K4: State Subject (Perpetrator) Count | L4: Subject (Perpetrator) to State Population | M4: Estimated Subject to City Population | N4: State Subject Losses (Perpetrator gained X dollars) | O4: Even Loss per State Subject | P4: Estimated In-City Subject Losses (Perpetrator Take from Victim)
B5: https://www2.census.gov/programs-surveys/popest/datasets/2020-2022/state/totals/NST-EST2022-POPCHG2020_2022.csv | C5: TN Population in 2021 | D5: Population Estimate | E5: 6968351 | F5: Raw Value | G5: (Victim Count/State Population ) * City Population | J5: Estimated In-City Victims * Even Loss per State Victim | P5: Subject to City * Even Loss per State Subject
B6: https://www.census.gov/data/tables/time-series/demo/popest/2020s-total-cities-and-towns.html | C6: Chattanooga Population in 2021 | D6: Population Estimate | E6: 181163
B7: https://www.ic3.gov/Media/PDF/AnnualReport/2021State/StateReport.aspx#?s=47 | C7: Advanced Fee | D7: State Victim Count | E7: 172 | F7: =E7/E5 | G7: =ROUNDDOWN(F7*E6,0) | H7: 2943621 | I7: =H7/E7 | J7: =I7*G7 | K7: 52 | L7: =K7/E5 | M7: =ROUNDDOWN(L7*E6,0) | N7: 98602 | O7: =N7/K7 | P7: =M7*O7
B8: https://www.ic3.gov/Media/PDF/AnnualReport/2021State/StateReport.aspx#?s=47 | C8: Business Email Compromise | D8: State Victim Count | E8: 321 | F8: =E8/E5 | G8: =ROUNDDOWN(F8*E6,0) | H8: 38847655 | I8: =H8/E8 | J8: =I8*G8 | K8: 52 | L8: =K8/E5 | M8: =ROUNDDOWN(L8*E6,0) | N8: 5165687 | O8: =N8/K8 | P8: =M8*O8
B9: https://www.ic3.gov/Media/PDF/AnnualReport/2021State/StateReport.aspx#?s=47 | C9: Botnet | D9: State Victim Count | E9: NO MATCH | F9: =E9/E5 | G9: =ROUNDDOWN(F9*E6,0) | H9: NO MATCH | I9: =H9/E9 | J9: =I9*G9 | L9: =K9/E5 | M9: =ROUNDDOWN(L9*E6,0) | O9: =N9/K9 | P9: =M9*O9
B10: https://www.ic3.gov/Media/PDF/AnnualReport/2021State/StateReport.aspx#?s=47 | C10: Confidence/Romance | D10: State Victim Count | E10: 366 | F10: =E10/E5 | G10: =ROUNDDOWN(F10*E6,0) | H10: 14569398 | I10: =H10/E10 | J10: =I10*G10 | K10: 162 | L10: =K10/E5 | M10: =ROUNDDOWN(L10*E6,0) | N10: 5152816 | O10: =N10/K10 | P10: =M10*O10
B11: https://www.ic3.gov/Media/PDF/AnnualReport/2021State/StateReport.aspx#?s=47 | C11: Check Fraud | D11: State Victim Count | E11: NO MATCH | F11: =E11/E5 | G11: =ROUNDDOWN(F11*E6,0) | H11: NO MATCH | I11: =H11/E11 | J11: =I11*G11 | L11: =K11/E5 | M11: =ROUNDDOWN(L11*E6,0) | O11: =N11/K11 | P11: =M11*O11
B12: https://www.ic3.gov/Media/PDF/AnnualReport/2021State/StateReport.aspx#?s=47 | C12: Crimes Against Children | D12: State Victim Count | E12: 29 | F12: =E12/E5 | G12: =ROUNDDOWN(F12*E6,0) | H12: 0 | I12: =H12/E12 | J12: =I12*G12 | K12: 12 | L12: =K12/E5 | M12: =ROUNDDOWN(L12*E6,0) | N12: 34078 | O12: =N12/K12 | P12: =M12*O12
B13: https://www.ic3.gov/Media/PDF/AnnualReport/2021State/StateReport.aspx#?s=47 | C13: Data Breach | D13: State Victim Count | E13: 21 | F13: =E13/E5 | G13: =ROUNDDOWN(F13*E6,0) | H13: 609113 | I13: =H13/E13 | J13: =I13*G13 | K13: 7 | L13: =K13/E5 | M13: =ROUNDDOWN(L13*E6,0) | N13: 540618 | O13: =N13/K13 | P13: =M13*O13
B14: https://www.ic3.gov/Media/PDF/AnnualReport/2021State/StateReport.aspx#?s=47 | C14: Employment | D14: State Victim Count | E14: 230 | F14: =E14/E5 | G14: =ROUNDDOWN(F14*E6,0) | H14: 2996197 | I14: =H14/E14 | J14: =I14*G14 | K14: 96 | L14: =K14/E5 | M14: =ROUNDDOWN(L14*E6,0) | N14: 1679416 | O14: =N14/K14 | P14: =M14*O14
B15: https://www.ic3.gov/Media/PDF/AnnualReport/2021State/StateReport.aspx#?s=47 | C15: Extortion | D15: State Victim Count | E15: 628 | F15: =E15/E5 | G15: =ROUNDDOWN(F15*E6,0) | H15: 362852 | I15: =H15/E15 | J15: =I15*G15 | K15: 77 | L15: =K15/E5 | M15: =ROUNDDOWN(L15*E6,0) | N15: 48710 | O15: =N15/K15 | P15: =M15*O15
B16: https://www.ic3.gov/Media/PDF/AnnualReport/2021State/StateReport.aspx#?s=47 | C16: Government Impersonation | D16: State Victim Count | E16: 220 | F16: =E16/E5 | G16: =ROUNDDOWN(F16*E6,0) | H16: 1053487 | I16: =H16/E16 | J16: =I16*G16 | K16: 23 | L16: =K16/E5 | M16: =ROUNDDOWN(L16*E6,0) | N16: 125849 | O16: =N16/K16 | P16: =M16*O16
B17: https://www.ic3.gov/Media/PDF/AnnualReport/2021State/StateReport.aspx#?s=47 | C17: Harassing/Stalking | D17: State Victim Count | E17: NO MATCH | F17: =E17/E5 | G17: =ROUNDDOWN(F17*E6,0) | H17: NO MATCH | I17: =H17/E17 | J17: =I17*G17 | L17: =K17/E5 | M17: =ROUNDDOWN(L17*E6,0) | O17: =N17/K17 | P17: =M17*O17
B18: https://www.ic3.gov/Media/PDF/AnnualReport/2021State/StateReport.aspx#?s=47 | C18: IPR/Counterfeit | D18: State Victim Count | E18: 60 | F18: =E18/E5 | G18: =ROUNDDOWN(F18*E6,0) | H18: 248288 | I18: =H18/E18 | J18: =I18*G18 | K18: 19 | L18: =K18/E5 | M18: =ROUNDDOWN(L18*E6,0) | N18: 11863 | O18: =N18/K18 | P18: =M18*O18
